<robot name="URDF_FRANCIS_ASSEM_Parallel_Jaw_Gripper_V3">
  <link name="pjg_body_link">
    <inertial>
      <origin xyz="0.0402105559601423 6.82990180219775E-06 6.21368335599834E-05" rpy="0 0 0" />
      <mass value="0.381434237025036" />
      <inertia ixx="0.000503295100541258" ixy="3.79871976925095E-08" ixz="-1.7090715231261E-08" iyy="0.000186567551889182" iyz="-2.42662963518357E-08" izz="0.000530331947560273" />
    </inertial>
    <visual>
      <origin xyz="0 0 0" rpy="0 0 0" />
      <geometry>
        <mesh filename="$(arg tool_mesh_dir)/pjg_body_link.STL" />
      </geometry>
      <material name="">
        <color rgba="0.298039215686275 0.298039215686275 0.298039215686275 1" />
      </material>
    </visual>
    <collision name="pjg_body_collision_link">
      <origin xyz="0 0 0" rpy="0 0 0" />
      <geometry>
        <mesh filename="$(arg tool_mesh_dir)/pjg_body_collision_link.STL" />
      </geometry>
    </collision>
  </link>
  <link name="finger_right_link">
    <inertial>
      <origin xyz="-0.0147376535872763 0.0878098966581815 4.2410611834065E-08" rpy="0 0 0" />
      <mass value="0.0246520031759402" />
      <inertia ixx="6.72897321360021E-06" ixy="-6.08946889250578E-08" ixz="1.43463025461354E-11" iyy="5.38961935228557E-06" iyz="-4.68490098110155E-12" izz="4.61768017461667E-06" />
    </inertial>
    <visual>
      <origin xyz="0 0 0" rpy="0 0 0" />
      <geometry>
        <mesh filename="$(arg tool_mesh_dir)/finger_right_link.STL" />
      </geometry>
      <material name="">
        <color rgba="0.250980392156863 0.250980392156863 0.250980392156863 1" />
      </material>
    </visual>
    <collision name="finger_right_collision_link">
      <origin xyz="0 0 0" rpy="0 0 0" />
      <geometry>
        <mesh filename="$(arg tool_mesh_dir)/finger_right_collision_link.STL" />
      </geometry>
    </collision>
  </link>
  <joint name="finger_right_joint" type="prismatic">
    <origin xyz="0.166855269271506 0 0" rpy="0 0 1.5707963267949" />
    <parent link="pjg_body_link" />
    <child link="finger_right_link" />
    <axis xyz="1 0 0" />
    <limit lower="-0.04" upper="0" effort="20.0" velocity="6.0" />
  </joint>
  <link name="aruco_fingertip_right_link">
    <inertial>
      <origin xyz="-3.30439794460173E-06 -9.90743941899075E-06 -0.000211787813161998" rpy="0 0 0" />
      <mass value="0.000123521493853863" />
      <inertia ixx="3.33209068564966E-09" ixy="3.38901369078053E-15" ixz="7.62400928007288E-14" iyy="3.32883778612981E-09" iyz="2.28587510762229E-13" izz="6.65796010218534E-09" />
    </inertial>
    <visual>
      <origin xyz="0 0 0" rpy="0 0 0" />
      <geometry>
        <mesh filename="$(arg tool_mesh_dir)/aruco_fingertip_right_link.STL" />
      </geometry>
      <material name="">
        <color rgba="1 1 1 1" />
      </material>
    </visual>
    <collision name="aruco_fingertip_right_collision_link">
      <origin xyz="0 0 0" rpy="0 0 0" />
      <geometry>
        <mesh filename="$(arg tool_mesh_dir)/aruco_fingertip_right_collision_link.STL" />
      </geometry>
    </collision>
  </link>
  <joint name="aruco_fingertip_right_joint" type="fixed">
    <origin xyz="-0.0122499999999998 0.0670400491408858 0.0169999999999987" rpy="0 0 -3.14159265358979" />
    <parent link="finger_right_link" />
    <child link="aruco_fingertip_right_link" />
    <axis xyz="0 0 0" />
  </joint>
  <link name="finger_left_link">
    <inertial>
      <origin xyz="-0.0147376535872763 -0.0878098966581815 -4.24106113818627E-08" rpy="0 0 0" />
      <mass value="0.0246520031759402" />
      <inertia ixx="6.72897321360021E-06" ixy="6.08946889250469E-08" ixz="-1.43463025447666E-11" iyy="5.38961935228542E-06" iyz="-4.68490098025683E-12" izz="4.61768017461652E-06" />
    </inertial>
    <visual>
      <origin xyz="0 0 0" rpy="0 0 0" />
      <geometry>
        <mesh filename="$(arg tool_mesh_dir)/finger_left_link.STL" />
      </geometry>
      <material name="">
        <color rgba="0.250980392156863 0.250980392156863 0.250980392156863 1" />
      </material>
    </visual>
    <collision name="finger_left_collision_link">
      <origin xyz="0 0 0" rpy="0 0 0" />
      <geometry>
        <mesh filename="$(arg tool_mesh_dir)/finger_left_collision_link.STL" />
      </geometry>
    </collision>
  </link>
  <joint name="finger_left_joint" type="prismatic">
    <origin xyz="0.166855269271506 0 0" rpy="0 0 -1.5707963267949" />
    <parent link="pjg_body_link" />
    <child link="finger_left_link" />
    <axis xyz="1 0 0" />
    <limit lower="-0.04" upper="0" effort="20.0" velocity="6.0" />
  </joint>
  <link name="aruco_fingertip_left_link">
    <inertial>
      <origin xyz="-3.30439794459479E-06 -9.90743941897687E-06 -0.000211787813161998" rpy="0 0 0" />
      <mass value="0.000123521493853863" />
      <inertia ixx="3.33209068564964E-09" ixy="3.38901369261042E-15" ixz="7.62400928004572E-14" iyy="3.32883778612979E-09" iyz="2.28587510767485E-13" izz="6.65796010218529E-09" />
    </inertial>
    <visual>
      <origin xyz="0 0 0" rpy="0 0 0" />
      <geometry>
        <mesh filename="$(arg tool_mesh_dir)/aruco_fingertip_left_link.STL" />
      </geometry>
      <material name="">
        <color rgba="1 1 1 1" />
      </material>
    </visual>
    <collision name="aruco_fingertip_left_collision_link">
      <origin xyz="0 0 0" rpy="0 0 0" />
      <geometry>
        <mesh filename="$(arg tool_mesh_dir)/aruco_fingertip_left_collision_link.STL" />
      </geometry>
    </collision>
  </link>
  <joint name="aruco_fingertip_left_joint" type="fixed">
    <origin xyz="-0.01225 -0.0670400491408859 0.0170000000000008" rpy="0 0 0" />
    <parent link="finger_left_link" />
    <child link="aruco_fingertip_left_link" />
    <axis xyz="0 0 0" />
  </joint>
  <link name="grasp_center_link" />
  <joint name="grasp_center_joint" type="fixed">
    <origin xyz="0.166855269271506 0 0" rpy="0 0 0" />
    <parent link="pjg_body_link" />
    <child link="grasp_center_link" />
    <axis xyz="0 0 0" />
  </joint>
  <link name="quick_connect_interface_link" />
  <joint name="quick_connect_interface_joint" type="fixed">
    <parent link="quick_connect_interface_link" />
    <child link="pjg_body_link" />
    <origin xyz="0 0 0" rpy="0 0 0" />
  </joint>
</robot>