<robot xmlns:xacro="http://www.ros.org/wiki/xacro" name="stretch">
  <link name="base_footprint">
    <visual>
      <origin xyz="0 0 0" rpy="0 0 0" />
      <geometry>
        <box size="0.001 0.001 0.001" /></geometry>
      <material name="">
        <color rgba="0.752941176470588 0.752941176470588 0.752941176470588 1" />
      </material>
    </visual>
    </link>
  <link name="base_link">
    <inertial>
      <origin xyz="0.000438847979959618 -0.00177714773743785 0.0964683696491897" rpy="0 0 0" />
      <mass value="18.9261042191275" />
      <inertia ixx="0.214992665976689" ixy="0.000833860434660833" ixz="-0.000588719185644081" iyy="0.223010418927309" iyz="-0.00155067412786042" izz="0.327845794874662" />
    </inertial>
    <visual>
      <origin xyz="0 0 0" rpy="0 0 0" />
      <geometry>
        <mesh filename="$(arg model_mesh_dir)/base_link.STL" />
      </geometry>
      <material name="">
        <color rgba="0.752941176470588 0.752941176470588 0.752941176470588 1" />
      </material>
    </visual>
    <collision name="base_collision_link">
      <origin xyz="0 0 0" rpy="0 0 0" />
      <geometry>
        <mesh filename="$(arg model_mesh_dir)/base_collision_link.STL" />
      </geometry>
    </collision>
  </link>
  <joint name="base_ref" type="fixed">
    <origin xyz="0 0 0.027999995691835" rpy="0 0 0" />
    <parent link="base_footprint" />
    <child link="base_link" />
    <axis xyz="0 0 0" />
  </joint>
  <link name="line_sensor_5_link">
    <inertial>
      <origin xyz="0.00114502070313141 -0.000126774756058531 0.0119761602719026" rpy="0 0 0" />
      <mass value="0.00213836003346436" />
      <inertia ixx="2.88698160050487E-07" ixy="-5.64135957062421E-10" ixz="-7.07831726662328E-09" iyy="2.34959277592962E-07" iyz="-2.73972720709966E-10" izz="6.64615782289848E-08" />
    </inertial>
    <collision name="line_sensor_5_collision_link">
      <origin xyz="0 0 0" rpy="0 0 0" />
      <geometry>
        <mesh filename="$(arg model_mesh_dir)/line_sensor_5_link.STL" />
      </geometry>
    </collision>
  </link>
  <joint name="line_sensor_5_joint" type="fixed">
    <origin xyz="0.0613832011662534 0.178318823151171 0.0527013981430276" rpy="0 0.453785605518531 1.04719755119659" />
    <parent link="base_link" />
    <child link="line_sensor_5_link" />
    <axis xyz="0 0 0" />
  </joint>
  <link name="line_sensor_5_optical_link">
    </link>
  <joint name="line_sensor_5_optical_joint" type="fixed">
    <origin xyz="0.00286000000000003 0 0" rpy="-1.5707963267949 0 -1.5707963267949" />
    <parent link="line_sensor_5_link" />
    <child link="line_sensor_5_optical_link" />
    <axis xyz="0 0 0" />
  </joint>
  <link name="line_sensor_4_link">
    <inertial>
      <origin xyz="0.00114502070313141 -0.000126774756058587 0.0119761602719026" rpy="0 0 0" />
      <mass value="0.00213836003346436" />
      <inertia ixx="2.88698160050488E-07" ixy="-5.64135957060019E-10" ixz="-7.07831726662323E-09" iyy="2.34959277592962E-07" iyz="-2.7397272070835E-10" izz="6.64615782289851E-08" />
    </inertial>
    <collision name="line_sensor_4_collision_link">
      <origin xyz="0 0 0" rpy="0 0 0" />
      <geometry>
        <mesh filename="$(arg model_mesh_dir)/line_sensor_4_link.STL" />
      </geometry>
    </collision>
  </link>
  <joint name="line_sensor_4_joint" type="fixed">
    <origin xyz="-0.0613832011662525 0.178318823151171 0.0527013981430276" rpy="0 0.453785605518532 2.09439510239319" />
    <parent link="base_link" />
    <child link="line_sensor_4_link" />
    <axis xyz="0 0 0" />
  </joint>
  <link name="line_sensor_4_optical_link">
    </link>
  <joint name="line_sensor_4_optical_joint" type="fixed">
    <origin xyz="0.00286 0 0" rpy="-1.5707963267949 0 -1.5707963267949" />
    <parent link="line_sensor_4_link" />
    <child link="line_sensor_4_optical_link" />
    <axis xyz="0 0 0" />
  </joint>
  <link name="line_sensor_3_link">
    <inertial>
      <origin xyz="0.00114502070313158 -0.000126774756058573 0.0119761602719024" rpy="0 0 0" />
      <mass value="0.00213836003346444" />
      <inertia ixx="2.88698160050477E-07" ixy="-5.64135957061258E-10" ixz="-7.07831726660266E-09" iyy="2.34959277592965E-07" iyz="-2.73972720709266E-10" izz="6.64615782289998E-08" />
    </inertial>
    <collision name="line_sensor_3_collision_link">
      <origin xyz="0 0 0" rpy="0 0 0" />
      <geometry>
        <mesh filename="$(arg model_mesh_dir)/line_sensor_3_link.STL" />
      </geometry>
    </collision>
  </link>
  <joint name="line_sensor_3_joint" type="fixed">
    <origin xyz="-0.185120231404985 -0.036 0.0527013981430276" rpy="0 0.453785605518531 -3.14159265358979" />
    <parent link="base_link" />
    <child link="line_sensor_3_link" />
    <axis xyz="0 0 0" />
  </joint>
  <link name="line_sensor_3_optical_link">
    </link>
  <joint name="line_sensor_3_optical_joint" type="fixed">
    <origin xyz="0.00286 0 0" rpy="-1.5707963267949 0 -1.5707963267949" />
    <parent link="line_sensor_3_link" />
    <child link="line_sensor_3_optical_link" />
    <axis xyz="0 0 0" />
  </joint>
  <link name="line_sensor_2_link">
    <inertial>
      <origin xyz="0.00114502070313144 -0.000126774756058531 0.0119761602719027" rpy="0 0 0" />
      <mass value="0.00213836003346437" />
      <inertia ixx="2.88698160050489E-07" ixy="-5.64135957062398E-10" ixz="-7.07831726662342E-09" iyy="2.34959277592963E-07" iyz="-2.73972720710033E-10" izz="6.64615782289851E-08" />
    </inertial>
    <collision name="line_sensor_2_collision_link">
      <origin xyz="0 0 0" rpy="0 0 0" />
      <geometry>
        <mesh filename="$(arg model_mesh_dir)/line_sensor_2_link.STL" />
      </geometry>
    </collision>
  </link>
  <joint name="line_sensor_2_joint" type="fixed">
    <origin xyz="-0.123737030238733 -0.14231882315117 0.0527013981430276" rpy="0 0.453785605518531 -2.0943951023932" />
    <parent link="base_link" />
    <child link="line_sensor_2_link" />
    <axis xyz="0 0 0" />
  </joint>
  <link name="line_sensor_2_optical_link">
    </link>
  <joint name="line_sensor_2_optical_joint" type="fixed">
    <origin xyz="0.00286 0 0" rpy="-1.5707963267949 0 -1.5707963267949" />
    <parent link="line_sensor_2_link" />
    <child link="line_sensor_2_optical_link" />
    <axis xyz="0 0 0" />
  </joint>
  <link name="line_sensor_1_link">
    <inertial>
      <origin xyz="0.00114502070313141 -0.000126774756058601 0.0119761602719027" rpy="0 0 0" />
      <mass value="0.00213836003346436" />
      <inertia ixx="2.88698160050487E-07" ixy="-5.64135957059992E-10" ixz="-7.07831726662327E-09" iyy="2.34959277592961E-07" iyz="-2.73972720708435E-10" izz="6.64615782289849E-08" />
    </inertial>
    <collision name="line_sensor_1_collision_link">
      <origin xyz="0 0 0" rpy="0 0 0" />
      <geometry>
        <mesh filename="$(arg model_mesh_dir)/line_sensor_1_link.STL" />
      </geometry>
    </collision>
  </link>
  <joint name="line_sensor_1_joint" type="fixed">
    <origin xyz="0.123737030238732 -0.142318823151171 0.0527013981430276" rpy="0 0.453785605518531 -1.0471975511966" />
    <parent link="base_link" />
    <child link="line_sensor_1_link" />
    <axis xyz="0 0 0" />
  </joint>
  <link name="line_sensor_1_optical_link">
    </link>
  <joint name="line_sensor_1_optical_joint" type="fixed">
    <origin xyz="0.00286 0 0" rpy="-1.5707963267949 0 -1.5707963267949" />
    <parent link="line_sensor_1_link" />
    <child link="line_sensor_1_optical_link" />
    <axis xyz="0 0 0" />
  </joint>
  <link name="sensor_0_link">
    <inertial>
      <origin xyz="0.00114502070313161 -0.000126774756058566 0.0119761602719025" rpy="0 0 0" />
      <mass value="0.00213836003346444" />
      <inertia ixx="2.88698160050477E-07" ixy="-5.64135957061261E-10" ixz="-7.0783172666026E-09" iyy="2.34959277592965E-07" iyz="-2.73972720709192E-10" izz="6.6461578229E-08" />
    </inertial>
    <visual>
      <origin xyz="0 0 0" rpy="0 0 0" />
      <geometry>
        <mesh filename="$(arg model_mesh_dir)/sensor_0_link.STL" />
      </geometry>
      <material name="">
        <color rgba="0.792156862745098 0.819607843137255 0.933333333333333 1" />
      </material>
    </visual>
    <collision name="sensor_0_collision_link">
      <origin xyz="0 0 0" rpy="0 0 0" />
      <geometry>
        <mesh filename="$(arg model_mesh_dir)/sensor_0_link.STL" />
      </geometry>
    </collision>
  </link>
  <joint name="line_sensor_0_joint" type="fixed">
    <origin xyz="0.185120231404985 -0.0360000000000004 0.0527013981430276" rpy="0 0.453785605518531 0" />
    <parent link="base_link" />
    <child link="sensor_0_link" />
    <axis xyz="0 0 0" />
  </joint>
  <link name="line_sensor_0_optical_link">
    </link>
  <joint name="line_sensor_0_optical_joint" type="fixed">
    <origin xyz="0.00286000000000003 0 0" rpy="-1.5707963267949 0 -1.5707963267949" />
    <parent link="sensor_0_link" />
    <child link="line_sensor_0_optical_link" />
    <axis xyz="0 0 0" />
  </joint>
  <link name="head_link">
    <inertial>
      <origin xyz="0.0578831450711745 0.0985910072575782 -0.0270263437535108" rpy="0 0 0" />
      <mass value="5.61843540939406" />
      <inertia ixx="0.0382731622600879" ixy="0.000202623770136033" ixz="0.00023164221061037" iyy="0.030632670593406" iyz="5.61616115268146E-05" izz="0.06400207843788" />
    </inertial>
    <visual>
      <origin xyz="0 0 0" rpy="0 0 0" />
      <geometry>
        <mesh filename="$(arg model_mesh_dir)/head_link.STL" />
      </geometry>
      <material name="">
        <color rgba="0.752941176470588 0.752941176470588 0.752941176470588 1" />
      </material>
    </visual>
    <collision name="head_collision_link">
      <origin xyz="0 0 0" rpy="0 0 0" />
      <geometry>
        <mesh filename="$(arg model_mesh_dir)/head_collision_link.STL" />
      </geometry>
    </collision>
  </link>
  <joint name="head_joint" type="fixed">
    <origin xyz="-0.0930000000000002 -0.0979999999999998 1.55900000430817" rpy="0 0 0" />
    <parent link="base_link" />
    <child link="head_link" />
    <axis xyz="0 0 0" />
  </joint>
  <link name="lidar_right_link">
    <inertial>
      <origin xyz="0.0766909452916591 0.0306840664060522 -0.123358114205568" rpy="0 0 0" />
      <mass value="5.62562935738041" />
      <inertia ixx="0.0492829863501232" ixy="-0.0015644794553125" ixz="0.0149316959819941" iyy="0.0349356509390749" iyz="0.0038003613530989" izz="0.048690719277915" />
    </inertial>
    <collision name="lidar_right_collision_link">
      <origin xyz="0 0 0" rpy="0 0 0" />
      <geometry>
        <mesh filename="$(arg model_mesh_dir)/lidar_right_link.STL" />
      </geometry>
    </collision>
  </link>
  <joint name="lidar_right_joint" type="fixed">
    <origin xyz="0.131744211811827 -0.0264137425448753 -0.0583279884119643" rpy="-3.05465659239941 0.781600065124168 2.39203005564319" />
    <parent link="head_link" />
    <child link="lidar_right_link" />
    <axis xyz="0 0 0" />
  </joint>
  <link name="lidar_left_link">
    <inertial>
      <origin xyz="-0.0761200642618001 0.0298724095594048 -0.122718664995054" rpy="0 0 0" />
      <mass value="5.62562935738041" />
      <inertia ixx="0.0495631508318921" ixy="0.00150375867091916" ixz="-0.0147241234604212" iyy="0.034541985578385" iyz="0.00388339874636518" izz="0.0488042201568361" />
    </inertial>
    <collision name="lidar_left_collision_link">
      <origin xyz="0 0 0" rpy="0 0 0" />
      <geometry>
        <mesh filename="$(arg model_mesh_dir)/lidar_left_link.STL" />
      </geometry>
    </collision>
  </link>
  <joint name="lidar_left_joint" type="fixed">
    <origin xyz="0.131744211811846 0.222413742544858 -0.0583279884119634" rpy="-3.05465659239939 -0.781600065124167 0.749562597946573" />
    <parent link="head_link" />
    <child link="lidar_left_link" />
    <axis xyz="0 0 0" />
  </joint>
  <link name="camera_right_link">
    <inertial>
      <origin xyz="-0.0693850700494765 -0.0909126816993031 -0.0755902514887177" rpy="0 0 0" />
      <mass value="5.62562935738041" />
      <inertia ixx="0.0518045670378194" ixy="-0.0128492794593393" ixz="-9.71150764634026E-05" iyy="0.0504717539658347" iyz="-0.000186491771284805" izz="0.0306330355634591" />
    </inertial>
    <collision name="camera_right_collision_link">
      <origin xyz="0 0 0" rpy="0 0 0" />
      <geometry>
        <mesh filename="$(arg model_mesh_dir)/camera_right_link.STL" />
      </geometry>
    </collision>
  </link>
  <joint name="camera_right_joint" type="fixed">
    <origin xyz="0.171840602787894 0.0230000000000032 -0.0157566987072475" rpy="1.5707963267949 0.820304748437337 0" />
    <parent link="head_link" />
    <child link="camera_right_link" />
    <axis xyz="0 0 0" />
  </joint>
  <link name="camera_right_optical_link">
    </link>
  <joint name="camera_right_optical_joint" type="fixed">
    <origin xyz="0.0212000000000001 0 0" rpy="-1.5707963267949 0 -1.5707963267949" />
    <parent link="camera_right_link" />
    <child link="camera_right_optical_link" />
    <axis xyz="0 0 0" />
  </joint>
  <link name="camera_left_link">
    <inertial>
      <origin xyz="-0.0693850700494769 0.0909126816993033 -0.0744097485112792" rpy="0 0 0" />
      <mass value="5.62562935738041" />
      <inertia ixx="0.0518045670378194" ixy="0.0128492794593393" ixz="9.71150764634441E-05" iyy="0.0504717539658347" iyz="-0.000186491771284775" izz="0.0306330355634591" />
    </inertial>
    <collision name="camera_left_collision_link">
      <origin xyz="0 0 0" rpy="0 0 0" />
      <geometry>
        <mesh filename="$(arg model_mesh_dir)/camera_left_link.STL" />
      </geometry>
    </collision>
  </link>
  <joint name="camera_left_joint" type="fixed">
    <origin xyz="0.171840602787895 0.173 -0.0157566987072475" rpy="-1.5707963267949 0.820304748437337 0" />
    <parent link="head_link" />
    <child link="camera_left_link" />
    <axis xyz="0 0 0" />
  </joint>
  <link name="camera_left_optical_link">
    </link>
  <joint name="camera_left_optical_joint" type="fixed">
    <origin xyz="0.0211999999999999 0 0" rpy="-1.5707963267949 0 -1.5707963267949" />
    <parent link="camera_left_link" />
    <child link="camera_left_optical_link" />
    <axis xyz="0 0 0" />
  </joint>
  <link name="camera_center_link">
    <inertial>
      <origin xyz="-0.0958729354978768 0.0709239731668885 0.000590251488720641" rpy="0 0 0" />
      <mass value="5.62562935738041" />
      <inertia ixx="0.0465206803724917" ixy="0.0120094528414331" ixz="0.000133766698529188" iyy="0.0557556406311624" iyz="-0.000162225118887399" izz="0.0306330355634591" />
    </inertial>
    <collision name="camera_center_collision_link">
      <origin xyz="0 0 0" rpy="0 0 0" />
      <geometry>
        <mesh filename="$(arg model_mesh_dir)/camera_center_link.STL" />
      </geometry>
    </collision>
  </link>
  <joint name="camera_center_joint" type="fixed">
    <origin xyz="0.177245603402412 0.0980000000000004 -0.0239069097938973" rpy="-1.5707963267949 0.610865238198018 0" />
    <parent link="head_link" />
    <child link="camera_center_link" />
    <axis xyz="0 0 0" />
  </joint>
  <link name="camera_center_optical_link">
    </link>
  <joint name="camera_center_optical_joint" type="fixed">
    <origin xyz="0.00170000000000003 0 0" rpy="-1.5707963267949 0 -1.5707963267949" />
    <parent link="camera_center_link" />
    <child link="camera_center_optical_link" />
    <axis xyz="0 0 0" />
  </joint>
  <link name="mast_link">
    <inertial>
      <origin xyz="2.77555756156289E-17 -0.00165282700965368 0.815" rpy="0 0 0" />
      <mass value="10.8924861076487" />
      <inertia ixx="1.96276319417158" ixy="-4.91253888692586E-18" ixz="-1.21184210498761E-16" iyy="1.96594229514087" iyz="-3.35011521318398E-18" izz="0.00577661764276332" />
    </inertial>
    <visual>
      <origin xyz="0 0 0" rpy="0 0 0" />
      <geometry>
        <mesh filename="$(arg model_mesh_dir)/mast_link.STL" />
      </geometry>
      <material name="">
        <color rgba="0.752941176470588 0.752941176470588 0.752941176470588 1" />
      </material>
    </visual>
    <collision name="mast_collision_link">
      <origin xyz="0 0 0" rpy="0 0 0" />
      <geometry>
        <mesh filename="$(arg model_mesh_dir)/mast_collision_link.STL" />
      </geometry>
    </collision>
  </link>
  <joint name="mast_joint" type="fixed">
    <origin xyz="-0.0930000000000002 -0.0979999999999998 0.00400000430816486" rpy="0 0 0" />
    <parent link="base_link" />
    <child link="mast_link" />
    <axis xyz="0 0 0" />
  </joint>
  <link name="lift_link">
    <inertial>
      <origin xyz="-0.0148722581318623 0.0596072894254191 0.00542773918494444" rpy="0 0 0" />
      <mass value="2.95349364666659" />
      <inertia ixx="0.0117399464230091" ixy="0.000875437380496019" ixz="0.000164784888522663" iyy="0.0102748963241433" iyz="-0.00101918054718661" izz="0.0139841484528854" />
    </inertial>
    <visual>
      <origin xyz="0 0 0" rpy="0 0 0" />
      <geometry>
        <mesh filename="$(arg model_mesh_dir)/lift_link.STL" />
      </geometry>
      <material name="">
        <color rgba="0.752941176470588 0.752941176470588 0.752941176470588 1" />
      </material>
    </visual>
    <collision name="lift_collision_link">
      <origin xyz="0 0 0" rpy="0 0 0" />
      <geometry>
        <mesh filename="$(arg model_mesh_dir)/lift_collision_link.STL" />
      </geometry>
    </collision>
  </link>
  <joint name="lift_joint" type="prismatic">
    <origin xyz="0 -0.00140000000000005 0.241" rpy="0 0 0" />
    <parent link="mast_link" />
    <child link="lift_link" />
    <axis xyz="0 0 1" />
    <limit lower="0" upper="1.2" effort="0" velocity="0" />
  </joint>
  <link name="arm_l0_link">
    <inertial>
      <origin xyz="-0.0316222581318623 -0.039792710574581 0.0182872881301621" rpy="0 0 0" />
      <mass value="2.95349364666659" />
      <inertia ixx="0.0117399464230091" ixy="0.000875437380496019" ixz="0.000164784888522662" iyy="0.0102748963241433" iyz="-0.00101918054718661" izz="0.0139841484528854" />
    </inertial>
    <visual>
      <origin xyz="0 0 0" rpy="0 0 0" />
      <geometry>
        <mesh filename="$(arg model_mesh_dir)/arm_l0_link.STL" />
      </geometry>
      <material name="">
        <color rgba="0.752941176470588 0.752941176470588 0.752941176470588 1" />
      </material>
    </visual>
    <collision name="arm_l0_collision_link">
      <origin xyz="0 0 0" rpy="0 0 0" />
      <geometry>
        <mesh filename="$(arg model_mesh_dir)/arm_l0_collision_link.STL" />
      </geometry>
    </collision>
  </link>
  <joint name="arm_l0_joint" type="fixed">
    <origin xyz="0.01675 0.0994000000000002 -0.0128595489452177" rpy="0 0 0" />
    <parent link="lift_link" />
    <child link="arm_l0_link" />
    <axis xyz="0 0 0" />
  </joint>
  <link name="arm_l1_link">
    <inertial>
      <origin xyz="0.0983194277508772 -6.17042026110449E-17 0.00214616065125611" rpy="0 0 0" />
      <mass value="0.211728696447344" />
      <inertia ixx="0.000227675228746485" ixy="1.42790510359093E-19" ixz="1.46222263181723E-10" iyy="0.000730798627565317" iyz="2.71815409206256E-21" izz="0.000759408092665036" />
    </inertial>
    <visual>
      <origin xyz="0 0 0" rpy="0 0 0" />
      <geometry>
        <mesh filename="$(arg model_mesh_dir)/arm_l1_link.STL" />
      </geometry>
      <material name="">
        <color rgba="0.752941176470588 0.752941176470588 0.752941176470588 1" />
      </material>
    </visual>
    <collision name="arm_l1_collision_link">
      <origin xyz="0 0 0" rpy="0 0 0" />
      <geometry>
        <mesh filename="$(arg model_mesh_dir)/arm_l1_collision_link.STL" />
      </geometry>
    </collision>
  </link>
  <joint name="arm_l1_joint" type="prismatic">
    <origin xyz="-0.01375 0 0" rpy="0 0 0" />
    <parent link="arm_l0_link" />
    <child link="arm_l1_link" />
    <axis xyz="1 0 0" />
    <limit lower="0" upper="0.13" effort="0" velocity="0" />
  </joint>
  <link name="arm_l2_link">
    <inertial>
      <origin xyz="0.126544808120785 -5.28822009914513E-17 0.00212532899607004" rpy="0 0 0" />
      <mass value="0.197181391808907" />
      <inertia ixx="0.000180704361161813" ixy="1.40253445285864E-19" ixz="1.56735722637944E-10" iyy="0.000676905139492615" iyz="-3.72122630710006E-21" izz="0.000701571828521803" />
    </inertial>
    <visual>
      <origin xyz="0 0 0" rpy="0 0 0" />
      <geometry>
        <mesh filename="$(arg model_mesh_dir)/arm_l2_link.STL" />
      </geometry>
      <material name="">
        <color rgba="0.752941176470588 0.752941176470588 0.752941176470588 1" />
      </material>
    </visual>
    <collision name="arm_l2_collision_link">
      <origin xyz="0 0 0" rpy="0 0 0" />
      <geometry>
        <mesh filename="$(arg model_mesh_dir)/arm_l2_collision_link.STL" />
      </geometry>
    </collision>
  </link>
  <joint name="arm_l2_joint" type="prismatic">
    <origin xyz="-0.0135000000000001 0 0" rpy="0 0 0" />
    <parent link="arm_l1_link" />
    <child link="arm_l2_link" />
    <axis xyz="1 0 0" />
    <limit lower="0" upper="0.13" effort="0" velocity="0" />
  </joint>
  <link name="arm_l3_link">
    <inertial>
      <origin xyz="0.154805576226277 -2.99487980435997E-17 0.00210076275486304" rpy="0 0 0" />
      <mass value="0.182379618165529" />
      <inertia ixx="0.000140464382352664" ixy="2.14407536327449E-19" ixz="1.68878152445003E-10" iyy="0.00062371110107317" iyz="-1.10859874912867E-20" izz="0.000644687237937217" />
    </inertial>
    <visual>
      <origin xyz="0 0 0" rpy="0 0 0" />
      <geometry>
        <mesh filename="$(arg model_mesh_dir)/arm_l3_link.STL" />
      </geometry>
      <material name="">
        <color rgba="0.752941176470588 0.752941176470588 0.752941176470588 1" />
      </material>
    </visual>
    <collision name="arm_l3_collision_link">
      <origin xyz="0 0 0" rpy="0 0 0" />
      <geometry>
        <mesh filename="$(arg model_mesh_dir)/arm_l3_collision_link.STL" />
      </geometry>
    </collision>
  </link>
  <joint name="arm_l3_joint" type="prismatic">
    <origin xyz="-0.0135 0 0" rpy="0 0 0" />
    <parent link="arm_l2_link" />
    <child link="arm_l3_link" />
    <axis xyz="1 0 0" />
    <limit lower="0" upper="0.13" effort="0" velocity="0" />
  </joint>
  <link name="arm_l4_link">
    <inertial>
      <origin xyz="0.15125 3.35236566452435E-16 0.00206007053977714" rpy="0 0 0" />
      <mass value="0.131482025176648" />
      <inertia ixx="7.61244098718923E-05" ixy="8.57509226382842E-20" ixz="-6.85841251548587E-20" iyy="0.00051464101554282" iyz="-4.71969502254436E-21" izz="0.000527876279377434" />
    </inertial>
    <visual>
      <origin xyz="0 0 0" rpy="0 0 0" />
      <geometry>
        <mesh filename="$(arg model_mesh_dir)/arm_l4_link.STL" />
      </geometry>
      <material name="">
        <color rgba="0.752941176470588 0.752941176470588 0.752941176470588 1" />
      </material>
    </visual>
    <collision name="arm_l4_collision_link">
      <origin xyz="0 0 0" rpy="0 0 0" />
      <geometry>
        <mesh filename="$(arg model_mesh_dir)/arm_l4_collision_link.STL" />
      </geometry>
    </collision>
  </link>
  <joint name="arm_l4_joint" type="prismatic">
    <origin xyz="-0.0055000000000001 0 0" rpy="0 0 0" />
    <parent link="arm_l3_link" />
    <child link="arm_l4_link" />
    <axis xyz="1 0 0" />
    <limit lower="0" upper="0.13" effort="0" velocity="0" />
  </joint>
  <link name="wrist_link">
    <inertial>
      <origin xyz="-0.00943224270685236 -2.24072494908036E-08 0.0350669907502222" rpy="0 0 0" />
      <mass value="0.228848612237181" />
      <inertia ixx="0.000122470482540944" ixy="-1.07472717291765E-10" ixz="1.16790939209657E-05" iyy="0.0001715213303575" iyz="-9.50304167695345E-11" izz="0.000141511317394913" />
    </inertial>
    <visual>
      <origin xyz="0 0 0" rpy="0 0 0" />
      <geometry>
        <mesh filename="$(arg model_mesh_dir)/wrist_link.STL" />
      </geometry>
      <material name="">
        <color rgba="0.501960784313725 0.501960784313725 0.501960784313725 1" />
      </material>
    </visual>
    <collision name="wrist_collision_link">
      <origin xyz="0 0 0" rpy="0 0 0" />
      <geometry>
        <mesh filename="$(arg model_mesh_dir)/wrist_collision_link.STL" />
      </geometry>
    </collision>
  </link>
  <joint name="wrist_joint" type="fixed">
    <origin xyz="0.2934 0 -0.03672" rpy="0 0 0" />
    <parent link="arm_l4_link" />
    <child link="wrist_link" />
    <axis xyz="0 0 0" />
  </joint>
  <link name="wrist_yaw_link">
    <inertial>
      <origin xyz="-8.08039203326061E-08 -0.00772611704050977 -0.0363542792860382" rpy="0 0 0" />
      <mass value="0.217322026723881" />
      <inertia ixx="0.000154147840230305" ixy="7.53840930670252E-11" ixz="-2.58411913184479E-10" iyy="0.000122233038608625" iyz="-1.61976028021007E-05" izz="0.000116712065914663" />
    </inertial>
    <visual>
      <origin xyz="0 0 0" rpy="0 0 0" />
      <geometry>
        <mesh filename="$(arg model_mesh_dir)/wrist_yaw_link.STL" />
      </geometry>
      <material name="">
        <color rgba="0.792156862745098 0.819607843137255 0.933333333333333 1" />
      </material>
    </visual>
    <collision name="wrist_yaw_collision_link">
      <origin xyz="0 0 0" rpy="0 0 0" />
      <geometry>
        <mesh filename="$(arg model_mesh_dir)/wrist_yaw_collision_link.STL" />
      </geometry>
    </collision>
  </link>
  <joint name="wrist_yaw_joint" type="revolute">
    <origin xyz="0 0 0" rpy="0 0 0" />
    <parent link="wrist_link" />
    <child link="wrist_yaw_link" />
    <axis xyz="0 0 1" />
    <limit lower="-1.135" upper="4.276" effort="0" velocity="0" />
  </joint>
  <link name="wrist_pitch_link">
    <inertial>
      <origin xyz="0.00772611704078718 -0.0363542792869388 8.08039212485401E-08" rpy="0 0 0" />
      <mass value="0.217322026722233" />
      <inertia ixx="0.000122233038607208" ixy="1.61976028024354E-05" ixz="7.53832441103333E-11" iyy="0.000116712065911208" iyz="2.58412492763863E-10" izz="0.000154147840226459" />
    </inertial>
    <visual>
      <origin xyz="0 0 0" rpy="0 0 0" />
      <geometry>
        <mesh filename="$(arg model_mesh_dir)/wrist_pitch_link.STL" />
      </geometry>
      <material name="">
        <color rgba="0.792156862745098 0.819607843137255 0.933333333333333 1" />
      </material>
    </visual>
    <collision name="wrist_pitch_collision_link">
      <origin xyz="0 0 0" rpy="0 0 0" />
      <geometry>
        <mesh filename="$(arg model_mesh_dir)/wrist_pitch_collision_link.STL" />
      </geometry>
    </collision>
  </link>
  <joint name="wrist_pitch_joint" type="revolute">
    <origin xyz="0 -0.0422200000000001 -0.0452000000000001" rpy="0 0 0" />
    <parent link="wrist_yaw_link" />
    <child link="wrist_pitch_link" />
    <axis xyz="0 -1 0" />
    <limit lower="-4.276" upper="1.135" effort="0" velocity="0" />
  </joint>
  <link name="wrist_roll_link">
    <inertial>
      <origin xyz="0.0125796209584655 0.00139059549833792 0.012231226279655" rpy="0 0 0" />
      <mass value="0.0875518779599177" />
      <inertia ixx="7.36573009473639E-05" ixy="1.09648627072304E-11" ixz="3.93918627087478E-06" iyy="5.3109684066939E-05" iyz="2.53579489920842E-10" izz="2.50172844184434E-05" />
    </inertial>
    <visual>
      <origin xyz="0 0 0" rpy="0 0 0" />
      <geometry>
        <mesh filename="$(arg model_mesh_dir)/wrist_roll_link.STL" />
      </geometry>
      <material name="">
        <color rgba="0.752941176470588 0.752941176470588 0.752941176470588 1" />
      </material>
    </visual>
    <collision name="wrist_roll_collision_link">
      <origin xyz="0 0 0" rpy="0 0 0" />
      <geometry>
        <mesh filename="$(arg model_mesh_dir)/wrist_roll_collision_link.STL" />
      </geometry>
    </collision>
  </link>
  <joint name="wrist_roll_joint" type="revolute">
    <origin xyz="0.0422200000000001 -0.0451999999999999 0" rpy="0 0 0" />
    <parent link="wrist_pitch_link" />
    <child link="wrist_roll_link" />
    <axis xyz="1 0 0" />
    <limit lower="-1.135" upper="4.276" effort="0" velocity="0" />
  </joint>
  <link name="gripper_camera_link">
    <inertial>
      <origin xyz="-0.0121348322776446 -1.38777878078145E-17 0.00187096264569653" rpy="0 0 0" />
      <mass value="0.0447759731526001" />
      <inertia ixx="1.60194001393268E-05" ixy="9.36418181523527E-22" ixz="9.91050471819132E-08" iyy="6.92267971098109E-06" iyz="-4.69734902377389E-22" izz="1.36285341071377E-05" />
    </inertial>
    <visual>
      <origin xyz="0 0 0" rpy="0 0 0" />
      <geometry>
        <mesh filename="$(arg model_mesh_dir)/gripper_camera_link.STL" />
      </geometry>
      <material name="">
        <color rgba="0.792156862745098 0.819607843137255 0.933333333333333 1" />
      </material>
    </visual>
    <collision name="gripper_camera_collision_link">
      <origin xyz="0 0 0" rpy="0 0 0" />
      <geometry>
        <mesh filename="$(arg model_mesh_dir)/gripper_camera_collision_link.STL" />
      </geometry>
    </collision>
  </link>
  <joint name="gripper_camera_joint" type="fixed">
    <origin xyz="0.0192000000000001 0 0.057" rpy="0 0.0523598775598298 0" />
    <parent link="wrist_roll_link" />
    <child link="gripper_camera_link" />
    <axis xyz="0 0 0" />
  </joint>
  <link name="gripper_stereo_camera_color_optical_frame">
    <visual>
      <origin xyz="0 0 0" rpy="0 0 0" />
      <geometry>
        <box size="0.001 0.001 0.001" /></geometry>
      <material name="">
        <color rgba="0.792156862745098 0.819607843137255 0.933333333333333 1" />
      </material>
    </visual>
    </link>
  <joint name="gripper_stereo_camera_color_optical_joint" type="fixed">
    <origin xyz="0 0 0" rpy="-1.5707963267949 -0.0523598775598298 0" />
    <parent link="gripper_camera_link" />
    <child link="gripper_stereo_camera_color_optical_frame" />
    <axis xyz="0 0 0" />
  </joint>
  <link name="gripper_right_camera_color_optical_frame">
    <visual>
      <origin xyz="0 0 0" rpy="0 0 0" />
      <geometry>
        <box size="0.001 0.001 0.001" /></geometry>
      <material name="">
        <color rgba="0.792156862745098 0.819607843137255 0.933333333333333 1" />
      </material>
    </visual>
    </link>
  <joint name="gripper_right_camera_color_optical_joint" type="fixed">
    <origin xyz="0 -0.01 0" rpy="-1.5707963267949 -0.0523598775598298 0" />
    <parent link="gripper_camera_link" />
    <child link="gripper_right_camera_color_optical_frame" />
    <axis xyz="0 0 0" />
  </joint>
  <link name="gripper_left_camera_color_optical_frame">
    <visual>
      <origin xyz="0 0 0" rpy="0 0 0" />
      <geometry>
        <box size="0.001 0.001 0.001" /></geometry>
      <material name="">
        <color rgba="0.792156862745098 0.819607843137255 0.933333333333333 1" />
      </material>
    </visual>
    </link>
  <joint name="gripper_left_camera_color_optical_joint" type="fixed">
    <origin xyz="0 0.01 0" rpy="-1.5707963267949 -0.0523598775598298 0" />
    <parent link="gripper_camera_link" />
    <child link="gripper_left_camera_color_optical_frame" />
    <axis xyz="0 0 0" />
  </joint>
  <link name="tool_attachment_site_link">
    <inertial>
      <origin xyz="-0.00602037904153455 0.00139059549833791 0.012231226279655" rpy="0 0 0" />
      <mass value="0.0875518779599177" />
      <inertia ixx="7.36573009473639E-05" ixy="1.09648627076813E-11" ixz="3.93918627087477E-06" iyy="5.3109684066939E-05" iyz="2.5357948992143E-10" izz="2.50172844184434E-05" />
    </inertial>
    <visual>
      <origin xyz="0 0 0" rpy="0 0 0" />
      <geometry>
        <mesh filename="$(arg model_mesh_dir)/tool_attachment_site_link.STL" />
      </geometry>
      <material name="">
        <color rgba="0.752941176470588 0.752941176470588 0.752941176470588 1" />
      </material>
    </visual>
    <collision name="tool_attachment_site_collision_link">
      <origin xyz="0 0 0" rpy="0 0 0" />
      <geometry>
        <mesh filename="$(arg model_mesh_dir)/tool_attachment_site_collision_link.STL" />
      </geometry>
    </collision>
  </link>
  <joint name="tool_attachment_site_joint" type="fixed">
    <origin xyz="0.0186 0 0" rpy="0 0 0" />
    <parent link="wrist_roll_link" />
    <child link="tool_attachment_site_link" />
    <axis xyz="0 0 0" />
  </joint>
  <link name="wrist_aruco_link">
    <inertial>
      <origin xyz="-8.97014059894619E-06 2.99075835221763E-06 -0.000313517411967446" rpy="0 0 0" />
      <mass value="0.000520487721584508" />
      <inertia ixx="3.834908442783E-08" ixy="-1.23630345810507E-14" ixz="1.34704395412492E-12" iyy="3.83685013633507E-08" iyz="-4.4912149519828E-13" izz="7.66888919510146E-08" />
    </inertial>
    <visual>
      <origin xyz="0 0 0" rpy="0 0 0" />
      <geometry>
        <mesh filename="$(arg model_mesh_dir)/wrist_aruco_link.STL" />
      </geometry>
      <material name="">
        <color rgba="1 1 1 1" />
      </material>
    </visual>
    <collision name="wrist_aruco_collision_link">
      <origin xyz="0 0 0" rpy="0 0 0" />
      <geometry>
        <mesh filename="$(arg model_mesh_dir)/wrist_aruco_collision_link.STL" />
      </geometry>
    </collision>
  </link>
  <joint name="wrist_aruco_joint" type="fixed">
    <origin xyz="-0.00867000000000001 0 0.0681104510547822" rpy="0 0 0" />
    <parent link="wrist_link" />
    <child link="wrist_aruco_link" />
    <axis xyz="0 0 0" />
  </joint>
  <link name="wrist_reflector_link">
    <inertial>
      <origin xyz="0.00377531872412074 -3.85449981286527E-12 0.00351760915937299" rpy="0 0 0" />
      <mass value="0.00171618092746856" />
      <inertia ixx="1.51127728759546E-07" ixy="1.29437561169358E-17" ixz="-1.24862425165547E-09" iyy="1.64146246077095E-08" iyz="-2.00458483084907E-17" izz="1.47242352409892E-07" />
    </inertial>
    <visual>
      <origin xyz="0 0 0" rpy="0 0 0" />
      <geometry>
        <mesh filename="$(arg model_mesh_dir)/wrist_reflector_link.STL" />
      </geometry>
      <material name="">
        <color rgba="1 1 1 1" />
      </material>
    </visual>
    <collision name="wrist_reflector_collision_link">
      <origin xyz="0 0 0" rpy="0 0 0" />
      <geometry>
        <mesh filename="$(arg model_mesh_dir)/wrist_reflector_collision_link.STL" />
      </geometry>
    </collision>
  </link>
  <joint name="wrist_reflector_joint" type="fixed">
    <origin xyz="0.00665000000000002 0 0.0677604510547822" rpy="0 0 0" />
    <parent link="wrist_link" />
    <child link="wrist_reflector_link" />
    <axis xyz="0 0 0" />
  </joint>
  <link name="wheel_2_link">
    <inertial>
      <origin xyz="1.25476756894562E-05 5.22307168604463E-06 -0.000275017600766342" rpy="0 0 0" />
      <mass value="6.0682081887272" />
      <inertia ixx="0.0154034644119385" ixy="-2.22604627484569E-06" ixz="5.21108774696477E-09" iyy="0.0154080256643557" iyz="5.27262855355176E-09" izz="0.029708346400951" />
    </inertial>
    <visual>
      <origin xyz="0 0 0" rpy="0 0 0" />
      <geometry>
        <mesh filename="$(arg model_mesh_dir)/wheel_2_link.STL" />
      </geometry>
      <material name="">
        <color rgba="0.752941176470588 0.752941176470588 0.752941176470588 1" />
      </material>
    </visual>
    <collision name="wheel_2_collision_link">
      <origin xyz="0 0 0" rpy="0 0 0" />
      <geometry>
        <mesh filename="$(arg model_mesh_dir)/wheel_2_collision_link.STL" />
      </geometry>
    </collision>
  </link>
  <joint name="wheel_2_joint" type="continuous">
    <origin xyz="0 -0.174 0.0720000043081651" rpy="-1.5707963267949 0 0" />
    <parent link="base_link" />
    <child link="wheel_2_link" />
    <axis xyz="0 0 1" />
  </joint>
  <link name="wheel_1_link">
    <inertial>
      <origin xyz="1.25478060125916E-05 5.22294298858916E-06 -0.00027501693981774" rpy="0 0 0" />
      <mass value="6.06820810020003" />
      <inertia ixx="0.0154034651258546" ixy="-2.22604258302274E-06" ixz="5.22035462687677E-09" iyy="0.0154080256614686" iyz="5.28562094393514E-09" izz="0.0297083471319844" />
    </inertial>
    <visual>
      <origin xyz="0 0 0" rpy="0 0 0" />
      <geometry>
        <mesh filename="$(arg model_mesh_dir)/wheel_1_link.STL" />
      </geometry>
      <material name="">
        <color rgba="0.752941176470588 0.752941176470588 0.752941176470588 1" />
      </material>
    </visual>
    <collision name="wheel_1_collision_link">
      <origin xyz="0 0 0" rpy="0 0 0" />
      <geometry>
        <mesh filename="$(arg model_mesh_dir)/wheel_1_collision_link.STL" />
      </geometry>
    </collision>
  </link>
  <joint name="wheel_1_joint" type="continuous">
    <origin xyz="-0.150688420258493 0.087000000000001 0.072000004308165" rpy="-1.5707963267949 0 -2.09439510239321" />
    <parent link="base_link" />
    <child link="wheel_1_link" />
    <axis xyz="0 0 1" />
  </joint>
  <link name="wheel_0_link">
    <inertial>
      <origin xyz="1.25474646742035E-05 5.22291550456022E-06 -0.000275016877356288" rpy="0 0 0" />
      <mass value="6.06820808425982" />
      <inertia ixx="0.0154034651445229" ixy="-2.22601000971658E-06" ixz="5.20622353301233E-09" iyy="0.0154080256540422" iyz="5.28522507564306E-09" izz="0.0297083471441777" />
    </inertial>
    <visual>
      <origin xyz="0 0 0" rpy="0 0 0" />
      <geometry>
        <mesh filename="$(arg model_mesh_dir)/wheel_0_link.STL" />
      </geometry>
      <material name="">
        <color rgba="0.752941176470588 0.752941176470588 0.752941176470588 1" />
      </material>
    </visual>
    <collision name="wheel_0_collision_link">
      <origin xyz="0 0 0" rpy="0 0 0" />
      <geometry>
        <mesh filename="$(arg model_mesh_dir)/wheel_0_collision_link.STL" />
      </geometry>
    </collision>
  </link>
  <joint name="wheel_0_joint" type="continuous">
    <origin xyz="0.150688420258492 0.0869999999999999 0.072000004308165" rpy="-1.5707963267949 0 2.09439510239319" />
    <parent link="base_link" />
    <child link="wheel_0_link" />
    <axis xyz="0 0 1" />
  </joint>
</robot>