<robot xmlns:xacro="http://www.ros.org/wiki/xacro" name="stretch">
  <link name="base_footprint">
    </link>
  <link name="base_link">
    <inertial>
      <origin xyz="0.000438847979959605 -0.00177714773743784 0.0964683588787771" rpy="0 0 0" />
      <mass value="18.9261042191275" />
      <inertia ixx="0.214992665976689" ixy="0.000833860434661022" ixz="-0.000588719185644055" iyy="0.223010418927309" iyz="-0.00155067412786045" izz="0.327845794874662" />
    </inertial>
    <visual>
      <origin xyz="0 0 0" rpy="0 0 0" />
      <geometry>
        <mesh filename="$(arg model_mesh_dir)/base_link.OBJ" />
      </geometry>
      <material name="">
        <color rgba="0.752941176470588 0.752941176470588 0.752941176470588 1" />
      </material>
    </visual>
    <collision name="base_collision_link">
      <origin xyz="0 0 0" rpy="0 0 0" />
      <geometry>
        <mesh filename="$(arg model_mesh_dir)/base_collision_link.OBJ" />
      </geometry>
    </collision>
  </link>
  <joint name="base_ref" type="fixed">
    <origin xyz="0 0 0.028" rpy="0 0 0" />
    <parent link="base_footprint" />
    <child link="base_link" />
    <axis xyz="0 0 0" />
  </joint>
  <link name="line_sensor_5_link">
    <inertial>
      <origin xyz="0.00114502 0.000126775 -0.0119762" rpy="1.5708 0 0" />
      <mass value="0.00213836003346436" />
      <inertia ixx="2.88698160050487E-07" ixy="-7.07831726662329E-09" ixz="5.64135957062429E-10" iyy="6.64615782289849E-08" iyz="2.73972720709955E-10" izz="2.34959277592962E-07" />
    </inertial>

  </link>
  <joint name="line_sensor_5_joint" type="fixed">
    <origin xyz="0.0613832 0.178319 0.0527014" rpy="0 0.453786 1.0472" />
    <parent link="base_link" />
    <child link="line_sensor_5_link" />
    <axis xyz="0 0 0" />
  </joint>
  <link name="line_sensor_5_optical_link">
    </link>
  <joint name="line_sensor_5_optical_joint" type="fixed">
    <origin xyz="0.00286 0 0" rpy="-1.5708 0 -1.5708" />
    <parent link="line_sensor_5_link" />
    <child link="line_sensor_5_optical_link" />
    <axis xyz="0 0 0" />
  </joint>
  <link name="line_sensor_4_link">
    <inertial>
      <origin xyz="0.00114502 0.000126775 -0.0119762" rpy="1.5708 0 0" />
      <mass value="0.00213836003346436" />
      <inertia ixx="2.88698160050488E-07" ixy="-7.07831726662323E-09" ixz="5.64135957060017E-10" iyy="6.6461578228985E-08" iyz="2.73972720708404E-10" izz="2.34959277592962E-07" />
    </inertial>

  </link>
  <joint name="line_sensor_4_joint" type="fixed">
    <origin xyz="-0.0613832 0.178319 0.0527014" rpy="0 0.453786 2.0944" />
    <parent link="base_link" />
    <child link="line_sensor_4_link" />
    <axis xyz="0 0 0" />
  </joint>
  <link name="line_sensor_4_optical_link">
    </link>
  <joint name="line_sensor_4_optical_joint" type="fixed">
    <origin xyz="0.00286 0 0" rpy="-1.5708 0 -1.5708" />
    <parent link="line_sensor_4_link" />
    <child link="line_sensor_4_optical_link" />
    <axis xyz="0 0 0" />
  </joint>
  <link name="line_sensor_3_link">
    <inertial>
      <origin xyz="0.00114502 0.000126775 -0.0119762" rpy="1.5708 0 0" />
      <mass value="0.00213836003346444" />
      <inertia ixx="2.88698160050477E-07" ixy="-7.07831726660264E-09" ixz="5.64135957061256E-10" iyy="6.64615782289998E-08" iyz="2.73972720709257E-10" izz="2.34959277592965E-07" />
    </inertial>

  </link>
  <joint name="line_sensor_3_joint" type="fixed">
    <origin xyz="-0.18512 -0.036 0.0527014" rpy="0 0.453786 -3.14159" />
    <parent link="base_link" />
    <child link="line_sensor_3_link" />
    <axis xyz="0 0 0" />
  </joint>
  <link name="line_sensor_3_optical_link">
    </link>
  <joint name="line_sensor_3_optical_joint" type="fixed">
    <origin xyz="0.00286 0 0" rpy="-1.5708 0 -1.5708" />
    <parent link="line_sensor_3_link" />
    <child link="line_sensor_3_optical_link" />
    <axis xyz="0 0 0" />
  </joint>
  <link name="line_sensor_2_link">
    <inertial>
      <origin xyz="0.00114502 0.000126775 -0.0119762" rpy="1.5708 0 0" />
      <mass value="0.00213836003346437" />
      <inertia ixx="2.88698160050488E-07" ixy="-7.07831726662343E-09" ixz="5.64135957062436E-10" iyy="6.64615782289851E-08" iyz="2.73972720710034E-10" izz="2.34959277592963E-07" />
    </inertial>

  </link>
  <joint name="line_sensor_2_joint" type="fixed">
    <origin xyz="-0.123737 -0.142319 0.0527014" rpy="0 0.453786 -2.0944" />
    <parent link="base_link" />
    <child link="line_sensor_2_link" />
    <axis xyz="0 0 0" />
  </joint>
  <link name="line_sensor_2_optical_link">
    </link>
  <joint name="line_sensor_2_optical_joint" type="fixed">
    <origin xyz="0.00286 0 0" rpy="-1.5708 0 -1.5708" />
    <parent link="line_sensor_2_link" />
    <child link="line_sensor_2_optical_link" />
    <axis xyz="0 0 0" />
  </joint>
  <link name="line_sensor_1_link">
    <inertial>
      <origin xyz="0.00114502 0.000126775 -0.0119762" rpy="1.5708 0 0" />
      <mass value="0.00213836003346436" />
      <inertia ixx="2.88698160050487E-07" ixy="-7.07831726662329E-09" ixz="5.64135957059983E-10" iyy="6.64615782289849E-08" iyz="2.73972720708449E-10" izz="2.34959277592962E-07" />
    </inertial>

  </link>
  <joint name="line_sensor_1_joint" type="fixed">
    <origin xyz="0.123737 -0.142319 0.0527014" rpy="0 0.453786 -1.0472" />
    <parent link="base_link" />
    <child link="line_sensor_1_link" />
    <axis xyz="0 0 0" />
  </joint>
  <link name="line_sensor_1_optical_link">
    </link>
  <joint name="line_sensor_1_optical_joint" type="fixed">
    <origin xyz="0.00286 0 0" rpy="-1.5708 0 -1.5708" />
    <parent link="line_sensor_1_link" />
    <child link="line_sensor_1_optical_link" />
    <axis xyz="0 0 0" />
  </joint>
  <link name="line_sensor_0_link">
    <inertial>
      <origin xyz="0.00114502 0.000126775 -0.0119762" rpy="1.5708 0 0" />
      <mass value="0.00213836003346444" />
      <inertia ixx="2.88698160050477E-07" ixy="-7.07831726660252E-09" ixz="5.64135957061258E-10" iyy="6.64615782290001E-08" iyz="2.73972720709191E-10" izz="2.34959277592965E-07" />
    </inertial>

  </link>
  <joint name="line_sensor_0_joint" type="fixed">
    <origin xyz="0.18512 -0.036 0.0527014" rpy="0 0.453786 0" />
    <parent link="base_link" />
    <child link="line_sensor_0_link" />
    <axis xyz="0 0 0" />
  </joint>
  <link name="line_sensor_0_optical_link">
    </link>
  <joint name="line_sensor_0_optical_joint" type="fixed">
    <origin xyz="0.00286 0 0" rpy="-1.5708 0 -1.5708" />
    <parent link="line_sensor_0_link" />
    <child link="line_sensor_0_optical_link" />
    <axis xyz="0 0 0" />
  </joint>
  <link name="head_link">
    <inertial>
      <origin xyz="0.0578831464809341 0.0985910077817881 -0.0270263436790745" rpy="0 0 0" />
      <mass value="5.618435167362" />
      <inertia ixx="0.0382731622122869" ixy="0.000202623919235895" ixz="0.000231642202175719" iyy="0.0306326706365949" iyz="5.61616354648268E-05" izz="0.0640020784749226" />
    </inertial>
    <visual>
      <origin xyz="0 0 0" rpy="0 0 0" />
      <geometry>
        <mesh filename="$(arg model_mesh_dir)/head_link.obj" />
      </geometry>
      <material name="">
        <color rgba="0.752941176470588 0.752941176470588 0.752941176470588 1" />
      </material>
    </visual>
    <collision name="head_collision_link">
      <origin xyz="0 0 0" rpy="0 0 0" />
      <geometry>
        <mesh filename="$(arg model_mesh_dir)/head_collision_link.obj" />
      </geometry>
    </collision>
  </link>
  <joint name="head_joint" type="fixed">
    <origin xyz="-0.093 -0.098 1.559" rpy="0 0 0" />
    <parent link="base_link" />
    <child link="head_link" />
    <axis xyz="0 0 0" />
  </joint>
  <link name="lidar_right_link">
    <inertial>
      <origin xyz="0.0766909447572703 0.0306840677846499 -0.12335811389925" rpy="0 0 0" />
      <mass value="5.62562911534835" />
      <inertia ixx="0.0492829862682945" ixy="-0.00156447943074778" ixz="0.0149316960757035" iyy="0.0349356510816738" iyz="0.00380036130478219" izz="0.0486907192495753" />
    </inertial>

  </link>
  <joint name="lidar_right_joint" type="fixed">
    <origin xyz="0.131744 -0.0264137 -0.058328" rpy="-3.05466 0.7816 2.39203" />
    <parent link="head_link" />
    <child link="lidar_right_link" />
    <axis xyz="0 0 0" />
  </joint>
  <link name="lidar_left_link">
    <inertial>
      <origin xyz="-0.0761200632210846 0.0298724102181261 -0.122718664121595" rpy="0 0 0" />
      <mass value="5.62562911534835" />
      <inertia ixx="0.0495631509325281" ixy="0.00150375861955282" ixz="-0.0147241234027668" iyy="0.0345419854283597" iyz="0.00388339874340473" izz="0.0488042202386559" />
    </inertial>

  </link>
  <joint name="lidar_left_joint" type="fixed">
    <origin xyz="0.131744 0.222414 -0.058328" rpy="-3.05466 -0.7816 0.749563" />
    <parent link="head_link" />
    <child link="lidar_left_link" />
    <axis xyz="0 0 0" />
  </joint>
  <link name="camera_right_link">
    <inertial>
      <origin xyz="-0.0755903 0.0693851 0.0909127" rpy="-1.5708 0 -1.5708" />
      <mass value="5.62562911534835" />
      <inertia ixx="0.0504717539490822" ixy="-0.000186491896655228" ixz="0.0128492795010695" iyy="0.0306330356066479" iyz="9.71151606421086E-05" izz="0.0518045670438135" />
    </inertial>

  </link>
  <joint name="camera_right_joint" type="fixed">
    <origin xyz="0.171841 0.023 -0.0157567" rpy="1.5708 0.820305 0" />
    <parent link="head_link" />
    <child link="camera_right_link" />
    <axis xyz="0 0 0" />
  </joint>
  <link name="camera_right_optical_link">
    </link>
  <joint name="camera_right_optical_joint" type="fixed">
    <origin xyz="0.0212 0 0" rpy="-1.5708 0 -1.5708" />
    <parent link="camera_right_link" />
    <child link="camera_right_optical_link" />
    <axis xyz="0 0 0" />
  </joint>
  <link name="camera_left_link">
    <inertial>
      <origin xyz="-0.0744097 0.0693851 -0.0909127" rpy="-1.5708 0 -1.5708" />
      <mass value="5.62562911534835" />
      <inertia ixx="0.0504717539490822" ixy="-0.000186491896655198" ixz="-0.0128492795010695" iyy="0.0306330356066479" iyz="-9.711516064215E-05" izz="0.0518045670438135" />
    </inertial>

  </link>
  <joint name="camera_left_joint" type="fixed">
    <origin xyz="0.171841 0.173 -0.0157567" rpy="-1.5708 0.820305 0" />
    <parent link="head_link" />
    <child link="camera_left_link" />
    <axis xyz="0 0 0" />
  </joint>
  <link name="camera_left_optical_link">
    </link>
  <joint name="camera_left_optical_joint" type="fixed">
    <origin xyz="0.0212 0 0" rpy="-1.5708 0 -1.5708" />
    <parent link="camera_left_link" />
    <child link="camera_left_optical_link" />
    <axis xyz="0 0 0" />
  </joint>
  <link name="camera_center_link">
    <inertial>
      <origin xyz="0.000590252 0.0958729 -0.070924" rpy="-1.5708 0 -1.5708" />
      <mass value="5.62562911534835" />
      <inertia ixx="0.0557556406323663" ixy="-0.000162225224016438" ixz="-0.0120094528841815" iyy="0.0306330356066479" iyz="-0.000133766806934365" izz="0.0465206803605294" />
    </inertial>

  </link>
  <joint name="camera_center_joint" type="fixed">
    <origin xyz="0.177246 0.098 -0.0239069" rpy="-1.5708 0.610865 0" />
    <parent link="head_link" />
    <child link="camera_center_link" />
    <axis xyz="0 0 0" />
  </joint>
  <link name="camera_center_optical_link">
    </link>
  <joint name="camera_center_optical_joint" type="fixed">
    <origin xyz="0.0017 0 0" rpy="-1.5708 0 -1.5708" />
    <parent link="camera_center_link" />
    <child link="camera_center_optical_link" />
    <axis xyz="0 0 0" />
  </joint>
  <link name="mast_link">
    <inertial>
      <origin xyz="2.77555756156289E-17 -0.00165282700965368 0.815" rpy="0 0 0" />
      <mass value="10.8924861076487" />
      <inertia ixx="1.96276319417158" ixy="-4.8379603279948E-18" ixz="-1.21184210498761E-16" iyy="1.96594229514087" iyz="-1.63360209238383E-18" izz="0.00577661764276332" />
    </inertial>
    <visual>
      <origin xyz="0 0 0" rpy="0 0 0" />
      <geometry>
        <mesh filename="$(arg model_mesh_dir)/mast_link.STL" />
      </geometry>
      <material name="">
        <color rgba="0.752941176470588 0.752941176470588 0.752941176470588 1" />
      </material>
    </visual>
    <collision name="mast_collision_link">
      <origin xyz="0 0 0" rpy="0 0 0" />
      <geometry>
        <mesh filename="$(arg model_mesh_dir)/mast_collision_link.STL" />
      </geometry>
    </collision>
  </link>
  <joint name="mast_joint" type="fixed">
    <origin xyz="-0.093 -0.098 0.004" rpy="0 0 0" />
    <parent link="base_link" />
    <child link="mast_link" />
    <axis xyz="0 0 0" />
  </joint>
  <link name="lift_link">
    <inertial>
      <origin xyz="-0.0148722581318624 0.0596072894254191 0.00542773918494444" rpy="0 0 0" />
      <mass value="2.95349364666659" />
      <inertia ixx="0.0117399464230091" ixy="0.000875437380496019" ixz="0.000164784888522663" iyy="0.0102748963241433" iyz="-0.00101918054718661" izz="0.0139841484528854" />
    </inertial>
    <visual>
      <origin xyz="0 0 0" rpy="0 0 0" />
      <geometry>
        <mesh filename="$(arg model_mesh_dir)/lift_link.STL" />
      </geometry>
      <material name="">
        <color rgba="0.752941176470588 0.752941176470588 0.752941176470588 1" />
      </material>
    </visual>
    <collision name="lift_collision_link">
      <origin xyz="0 0 0" rpy="0 0 0" />
      <geometry>
        <mesh filename="$(arg model_mesh_dir)/lift_collision_link.STL" />
      </geometry>
    </collision>
  </link>
  <joint name="lift_joint" type="prismatic">
    <origin xyz="0 -0.0014 0.241" rpy="0 0 0" />
    <parent link="mast_link" />
    <child link="lift_link" />
    <axis xyz="0 0 1" />
    <limit lower="0" upper="1.2" effort="0" velocity="0" />
  </joint>
  <link name="arm_l0_link">
    <inertial>
      <origin xyz="-0.0146277 -0.0397927 -0.0182873" rpy="0 1.5708 0" />
      <mass value="2.95349364666659" />
      <inertia ixx="0.0139841484528854" ixy="0.00101918054718661" ixz="-0.000164784888522662" iyy="0.0102748963241433" iyz="0.000875437380496019" izz="0.0117399464230091" />
    </inertial>
    <visual>
      <origin xyz="0 0 0" rpy="0 1.5708 0" />
      <geometry>
        <mesh filename="$(arg model_mesh_dir)/arm_l4_link.STL" />
      </geometry>
      <material name="">
        <color rgba="0.752941176470588 0.752941176470588 0.752941176470588 1" />
      </material>
    </visual>
    <collision name="arm_l0_collision_link">
      <origin xyz="0 0 0" rpy="0 1.5708 0" />
      <geometry>
        <mesh filename="$(arg model_mesh_dir)/arm_l4_collision_link.STL" />
      </geometry>
    </collision>
  </link>
  <joint name="arm_l0_joint" type="fixed">
    <origin xyz="-0.0295 0.0994 -0.0128595" rpy="0 0 0" />
    <parent link="lift_link" />
    <child link="arm_l0_link" />
    <axis xyz="0 0 0" />
  </joint>
  <link name="arm_l1_link">
    <inertial>
      <origin xyz="-0.125319 0 -0.00214616" rpy="0 1.5708 0" />
      <mass value="0.211728696447344" />
      <inertia ixx="0.000759408092665036" ixy="1.25607873437493E-20" ixz="-1.462222631837E-10" iyy="0.000730798627565317" iyz="1.43560898608883E-19" izz="0.000227675228746485" />
    </inertial>
    <visual>
      <origin xyz="0 0 0" rpy="0 1.5708 0" />
      <geometry>
        <mesh filename="$(arg model_mesh_dir)/arm_l3_link.STL" />
      </geometry>
      <material name="">
        <color rgba="0.752941176470588 0.752941176470588 0.752941176470588 1" />
      </material>
    </visual>
    <collision name="arm_l1_collision_link">
      <origin xyz="0 0 0" rpy="0 1.5708 0" />
      <geometry>
        <mesh filename="$(arg model_mesh_dir)/arm_l3_collision_link.STL" />
      </geometry>
    </collision>
  </link>
  <joint name="arm_l1_joint" type="prismatic">
    <origin xyz="0.0055 0 0" rpy="0 0 0" />
    <parent link="arm_l0_link" />
    <child link="arm_l1_link" />
    <axis xyz="1 0 0" />
    <limit lower="0" upper="0.13" effort="0" velocity="0" />
  </joint>
  <link name="arm_l2_link">
    <inertial>
      <origin xyz="-0.126545 0 -0.00212533" rpy="0 1.5708 0" />
      <mass value="0.197181391808907" />
      <inertia ixx="0.000701571828521802" ixy="1.2210188477606E-20" ixz="-1.56735722643836E-10" iyy="0.000676905139492614" iyz="1.82424630948924E-19" izz="0.000180704361161813" />
    </inertial>
    <visual>
      <origin xyz="0 0 0" rpy="0 1.5708 0" />
      <geometry>
        <mesh filename="$(arg model_mesh_dir)/arm_l2_link.STL" />
      </geometry>
      <material name="">
        <color rgba="0.752941176470588 0.752941176470588 0.752941176470588 1" />
      </material>
    </visual>
    <collision name="arm_l2_collision_link">
      <origin xyz="0 0 0" rpy="0 1.5708 0" />
      <geometry>
        <mesh filename="$(arg model_mesh_dir)/arm_l2_collision_link.STL" />
      </geometry>
    </collision>
  </link>
  <joint name="arm_l2_joint" type="prismatic">
    <origin xyz="0.0135 0 0" rpy="0 0 0" />
    <parent link="arm_l1_link" />
    <child link="arm_l2_link" />
    <axis xyz="1 0 0" />
    <limit lower="0" upper="0.13" effort="0" velocity="0" />
  </joint>
  <link name="arm_l3_link">
    <inertial>
      <origin xyz="-0.127806 0 -0.00210076" rpy="0 1.5708 0" />
      <mass value="0.182379618165529" />
      <inertia ixx="0.000644687237937217" ixy="1.27226721388911E-20" ixz="-1.68878152392632E-10" iyy="0.00062371110107317" iyz="1.87316065901084E-19" izz="0.000140464382352664" />
    </inertial>
    <visual>
      <origin xyz="0 0 0" rpy="0 1.5708 0" />
      <geometry>
        <mesh filename="$(arg model_mesh_dir)/arm_l1_link.STL" />
      </geometry>
      <material name="">
        <color rgba="0.752941176470588 0.752941176470588 0.752941176470588 1" />
      </material>
    </visual>
    <collision name="arm_l3_collision_link">
      <origin xyz="0 0 0" rpy="0 1.5708 0" />
      <geometry>
        <mesh filename="$(arg model_mesh_dir)/arm_l1_collision_link.STL" />
      </geometry>
    </collision>
  </link>
  <joint name="arm_l3_joint" type="prismatic">
    <origin xyz="0.0135 0 0" rpy="0 0 0" />
    <parent link="arm_l2_link" />
    <child link="arm_l3_link" />
    <axis xyz="1 0 0" />
    <limit lower="0" upper="0.13" effort="0" velocity="0" />
  </joint>
  <link name="arm_l4_link">
    <inertial>
      <origin xyz="-0.105 0 -0.00206007" rpy="0 1.5708 0" />
      <mass value="0.131482025176648" />
      <inertia ixx="0.000527876279377435" ixy="1.62475717205355E-20" ixz="7.67611440114497E-20" iyy="0.000514641015542821" iyz="1.71873232765738E-19" izz="7.61244098718923E-05" />
    </inertial>
    <visual>
      <origin xyz="0 0 0" rpy="0 1.5708 0" />
      <geometry>
        <mesh filename="$(arg model_mesh_dir)/arm_l0_link.STL" />
      </geometry>
      <material name="">
        <color rgba="0.752941176470588 0.752941176470588 0.752941176470588 1" />
      </material>
    </visual>
    <collision name="arm_l4_collision_link">
      <origin xyz="0 0 0" rpy="0 1.5708 0" />
      <geometry>
        <mesh filename="$(arg model_mesh_dir)/arm_l0_collision_link.STL" />
      </geometry>
    </collision>
  </link>
  <joint name="arm_l4_joint" type="prismatic">
    <origin xyz="0.01375 0 0" rpy="0 0 0" />
    <parent link="arm_l3_link" />
    <child link="arm_l4_link" />
    <axis xyz="1 0 0" />
    <limit lower="0" upper="0.13" effort="0" velocity="0" />
  </joint>
  <link name="wrist_link">
    <inertial>
      <origin xyz="-0.00943224 0 0.035067" rpy="3.14159 0 3.14159" />
      <mass value="0.228848612237181" />
      <inertia ixx="0.000122470482540944" ixy="1.07472717304307E-10" ixz="1.16790939209657E-05" iyy="0.0001715213303575" iyz="9.50304167596707E-11" izz="0.000141511317394913" />
    </inertial>
    <visual>
      <origin xyz="0 0 0" rpy="3.14159 0 3.14159" />
      <geometry>
        <mesh filename="$(arg model_mesh_dir)/wrist_link.STL" />
      </geometry>
      <material name="">
        <color rgba="0.501960784313725 0.501960784313725 0.501960784313725 1" />
      </material>
    </visual>
    <collision name="wrist_collision_link">
      <origin xyz="0 0 0" rpy="3.14159 0 3.14159" />
      <geometry>
        <mesh filename="$(arg model_mesh_dir)/wrist_collision_link.STL" />
      </geometry>
    </collision>
  </link>
  <joint name="wrist_joint" type="fixed">
    <origin xyz="0.24715 0 -0.03672" rpy="0 0 0" />
    <parent link="arm_l4_link" />
    <child link="wrist_link" />
    <axis xyz="0 0 0" />
  </joint>
  <link name="wrist_yaw_link">
    <inertial>
      <origin xyz="0 -0.00772612 -0.0363543" rpy="3.14159 0 3.14159" />
      <mass value="0.217322026723881" />
      <inertia ixx="0.000154147840230305" ixy="-7.53840930669222E-11" ixz="-2.58411913177616E-10" iyy="0.000122233038608625" iyz="1.61976028021007E-05" izz="0.000116712065914663" />
    </inertial>
    <visual>
      <origin xyz="0 0 0" rpy="3.14159 0 3.14159" />
      <geometry>
        <mesh filename="$(arg model_mesh_dir)/wrist_yaw_link.STL" />
      </geometry>
      <material name="">
        <color rgba="0.792156862745098 0.819607843137255 0.933333333333333 1" />
      </material>
    </visual>
    <collision name="wrist_yaw_collision_link">
      <origin xyz="0 0 0" rpy="3.14159 0 3.14159" />
      <geometry>
        <mesh filename="$(arg model_mesh_dir)/wrist_yaw_collision_link.STL" />
      </geometry>
    </collision>
  </link>
  <joint name="wrist_yaw_joint" type="revolute">
    <origin xyz="0 0 0" rpy="0 0 0" />
    <parent link="wrist_link" />
    <child link="wrist_yaw_link" />
    <axis xyz="0 0 1" />
    <limit lower="-1.135" upper="4.276" effort="0" velocity="0" />
  </joint>
  <link name="wrist_pitch_link">
    <inertial>
      <origin xyz="0.0363543 0 0.00772612" rpy="1.5708 -1.5708 0" />
      <mass value="0.217322026723367" />
      <inertia ixx="0.000154147840215896" ixy="-7.53836175868624E-11" ixz="-2.5841318678911E-10" iyy="0.000122233038608041" iyz="1.61976028014723E-05" izz="0.0001167120659007" />
    </inertial>
    <visual>
      <origin xyz="0 0 0" rpy="1.5708 -1.5708 0" />
      <geometry>
        <mesh filename="$(arg model_mesh_dir)/wrist_pitch_link.STL" />
      </geometry>
      <material name="">
        <color rgba="0.792156862745098 0.819607843137255 0.933333333333333 1" />
      </material>
    </visual>
    <collision name="wrist_pitch_collision_link">
      <origin xyz="0 0 0" rpy="1.5708 -1.5708 0" />
      <geometry>
        <mesh filename="$(arg model_mesh_dir)/wrist_pitch_collision_link.STL" />
      </geometry>
    </collision>
  </link>
  <joint name="wrist_pitch_joint" type="revolute">
    <origin xyz="0 -0.04222 -0.0452" rpy="0 0 0" />
    <parent link="wrist_yaw_link" />
    <child link="wrist_pitch_link" />
    <axis xyz="0 1 0" />
    <limit lower="-4.276" upper="1.135" effort="0" velocity="0" />
  </joint>
  <link name="wrist_roll_link">
    <inertial>
      <origin xyz="0.0122312 0.0125796 0.0013906" rpy="1.5708 0 1.5708" />
      <mass value="0.0875518779599176" />
      <inertia ixx="5.3109684066939E-05" ixy="2.53579489922607E-10" ixz="1.09648627067438E-11" iyy="2.50172844184434E-05" iyz="3.93918627087477E-06" izz="7.36573009473639E-05" />
    </inertial>
    <visual>
      <origin xyz="0 0 0" rpy="1.5708 0 1.5708" />
      <geometry>
        <mesh filename="$(arg model_mesh_dir)/wrist_roll_link.STL" />
      </geometry>
      <material name="">
        <color rgba="0.752941176470588 0.752941176470588 0.752941176470588 1" />
      </material>
    </visual>
    <collision name="wrist_roll_collision_link">
      <origin xyz="0 0 0" rpy="1.5708 0 1.5708" />
      <geometry>
        <mesh filename="$(arg model_mesh_dir)/wrist_roll_collision_link.STL" />
      </geometry>
    </collision>
  </link>
  <joint name="wrist_roll_joint" type="revolute">
    <origin xyz="0.04222 -0.0452 0" rpy="0 0 0" />
    <parent link="wrist_pitch_link" />
    <child link="wrist_roll_link" />
    <axis xyz="1 0 0" />
    <limit lower="-1.135" upper="4.276" effort="0" velocity="0" />
  </joint>
  <link name="gripper_camera_link">
    <inertial>
      <origin xyz="-0.0120203 0 0.00250349" rpy="-3.14159 0 0" />
      <mass value="0.0447759731526001" />
      <inertia ixx="1.60232107304684E-05" ixy="-8.93448675211009E-22" ixz="2.63946367478604E-08" iyy="6.92267971098109E-06" iyz="-5.28477827718936E-22" izz="1.36247235159961E-05" />
    </inertial>
    <visual>
      <origin xyz="0 0 0" rpy="-3.14159 0 0" />
      <geometry>
        <mesh filename="$(arg model_mesh_dir)/gripper_camera_link.STL" />
      </geometry>
      <material name="">
        <color rgba="0.792156862745098 0.819607843137255 0.933333333333333 1" />
      </material>
    </visual>
    <collision name="gripper_camera_collision_link">
      <origin xyz="0 0 0" rpy="-3.14159 0 0" />
      <geometry>
        <mesh filename="$(arg model_mesh_dir)/gripper_camera_collision_link.STL" />
      </geometry>
    </collision>
  </link>
  <joint name="gripper_camera_joint" type="fixed">
    <origin xyz="0.0192 0 0.057" rpy="0 0 0" />
    <parent link="wrist_roll_link" />
    <child link="gripper_camera_link" />
    <axis xyz="0 0 0" />
  </joint>
  <link name="gripper_stereo_camera_color_optical_frame">
    <visual>
      <origin xyz="0 0 0" rpy="1.5708 -1.5708 0" />
      <geometry>
        <box size="0.001 0.001 0.001" /></geometry>
      <material name="">
        <color rgba="0.792156862745098 0.819607843137255 0.933333333333333 1" />
      </material>
    </visual>
    </link>
  <joint name="gripper_stereo_camera_color_optical_joint" type="fixed">
    <origin xyz="0 0 0" rpy="-1.5708 0 -1.5708" />
    <parent link="gripper_camera_link" />
    <child link="gripper_stereo_camera_color_optical_frame" />
    <axis xyz="0 0 0" />
  </joint>
  <link name="gripper_right_camera_color_optical_frame">
    <visual>
      <origin xyz="0 0 0" rpy="1.5708 -1.5708 0" />
      <geometry>
        <box size="0.001 0.001 0.001" /></geometry>
      <material name="">
        <color rgba="0.792156862745098 0.819607843137255 0.933333333333333 1" />
      </material>
    </visual>
    </link>
  <joint name="gripper_right_camera_color_optical_joint" type="fixed">
    <origin xyz="0 -0.01 0" rpy="-1.5708 0 -1.5708" />
    <parent link="gripper_camera_link" />
    <child link="gripper_right_camera_color_optical_frame" />
    <axis xyz="0 0 0" />
  </joint>
  <link name="gripper_left_camera_color_optical_frame">
    <visual>
      <origin xyz="0 0 0" rpy="1.5708 -1.5708 0" />
      <geometry>
        <box size="0.001 0.001 0.001" /></geometry>
      <material name="">
        <color rgba="0.792156862745098 0.819607843137255 0.933333333333333 1" />
      </material>
    </visual>
    </link>
  <joint name="gripper_left_camera_color_optical_joint" type="fixed">
    <origin xyz="0 0.01 0" rpy="-1.5708 0 -1.5708" />
    <parent link="gripper_camera_link" />
    <child link="gripper_left_camera_color_optical_frame" />
    <axis xyz="0 0 0" />
  </joint>
  <link name="tool_attachment_site_link">
    <inertial>
      <origin xyz="-0.00602038 0.0013906 0.0122312" rpy="-3.14159 -1.5708 0" />
      <mass value="0.0875518779599177" />
      <inertia ixx="2.50172844184434E-05" ixy="-2.53579489915951E-10" ixz="3.93918627087477E-06" iyy="5.3109684066939E-05" iyz="-1.09648626721058E-11" izz="7.36573009473639E-05" />
    </inertial>
    <visual>
      <origin xyz="0 0 0" rpy="-3.14159 -1.5708 0" />
      <geometry>
        <mesh filename="$(arg model_mesh_dir)/tool_attachment_site_link.STL" />
      </geometry>
      <material name="">
        <color rgba="0.752941176470588 0.752941176470588 0.752941176470588 1" />
      </material>
    </visual>
    <collision name="tool_attachment_site_collision_link">
      <origin xyz="0 0 0" rpy="-3.14159 -1.5708 0" />
      <geometry>
        <mesh filename="$(arg model_mesh_dir)/tool_attachment_site_collision_link.STL" />
      </geometry>
    </collision>
  </link>
  <joint name="tool_attachment_site_joint" type="fixed">
    <origin xyz="0.0186 0 0" rpy="0 0 0" />
    <parent link="wrist_roll_link" />
    <child link="tool_attachment_site_link" />
    <axis xyz="0 0 0" />
  </joint>
  <link name="wrist_aruco_link">
    <inertial>
      <origin xyz="-8.97014059894619E-06 2.99075835221856E-06 -0.000313517411967446" rpy="0 0 0" />
      <mass value="0.000520487721584508" />
      <inertia ixx="3.834908442783E-08" ixy="-1.23630345809769E-14" ixz="1.34704395412488E-12" iyy="3.83685013633507E-08" iyz="-4.49121495198341E-13" izz="7.66888919510146E-08" />
    </inertial>
    <visual>
      <origin xyz="0 0 0" rpy="0 0 0" />
      <geometry>
        <mesh filename="$(arg model_mesh_dir)/wrist_aruco_link.STL" />
      </geometry>
      <material name="">
        <color rgba="1 1 1 1" />
      </material>
    </visual>
    <collision name="wrist_aruco_collision_link">
      <origin xyz="0 0 0" rpy="0 0 0" />
      <geometry>
        <mesh filename="$(arg model_mesh_dir)/wrist_aruco_collision_link.STL" />
      </geometry>
    </collision>
  </link>
  <joint name="wrist_aruco_joint" type="fixed">
    <origin xyz="-0.00867 0 0.0681105" rpy="0 0 0" />
    <parent link="wrist_link" />
    <child link="wrist_aruco_link" />
    <axis xyz="0 0 0" />
  </joint>
  <link name="wrist_reflector_link">
    <inertial>
      <origin xyz="0.00377531872412062 -3.85556640940668E-12 0.00351760915937294" rpy="0 0 0" />
      <mass value="0.00171618092746856" />
      <inertia ixx="1.51127728759546E-07" ixy="1.29437516845502E-17" ixz="-1.24862425165547E-09" iyy="1.64146246077095E-08" iyz="-2.00458412198489E-17" izz="1.47242352409892E-07" />
    </inertial>
    <visual>
      <origin xyz="0 0 0" rpy="0 0 0" />
      <geometry>
        <mesh filename="$(arg model_mesh_dir)/wrist_reflector_link.STL" />
      </geometry>
      <material name="">
        <color rgba="1 1 1 1" />
      </material>
    </visual>
    <collision name="wrist_reflector_collision_link">
      <origin xyz="0 0 0" rpy="0 0 0" />
      <geometry>
        <mesh filename="$(arg model_mesh_dir)/wrist_reflector_collision_link.STL" />
      </geometry>
    </collision>
  </link>
  <joint name="wrist_reflector_joint" type="fixed">
    <origin xyz="0.00665 0 0.0677605" rpy="0 0 0" />
    <parent link="wrist_link" />
    <child link="wrist_reflector_link" />
    <axis xyz="0 0 0" />
  </joint>
  <link name="wheel_2_link">
    <inertial>
      <origin xyz="1.25477e-05 5.22307e-06 -0.000275018" rpy="3.14159 0 -3.14159" />
      <mass value="6.0682081887272" />
      <inertia ixx="0.0154034644119385" ixy="2.22604627484513E-06" ixz="5.21108774702154E-09" iyy="0.0154080256643557" iyz="-5.27262855356677E-09" izz="0.029708346400951" />
    </inertial>
    <visual>
      <origin xyz="0 0 0" rpy="3.14159 0 -3.14159" />
      <geometry>
        <mesh filename="$(arg model_mesh_dir)/wheel_2_link.STL" />
      </geometry>
      <material name="">
        <color rgba="0.752941176470588 0.752941176470588 0.752941176470588 1" />
      </material>
    </visual>
    <collision name="wheel_2_collision_link">
      <origin xyz="0 0 0" rpy="3.14159 0 -3.14159" />
      <geometry>
        <mesh filename="$(arg model_mesh_dir)/wheel_2_collision_link.STL" />
      </geometry>
    </collision>
  </link>
  <joint name="wheel_2_joint" type="continuous">
    <origin xyz="0 -0.174 0.072" rpy="-1.5708 0 0" />
    <parent link="base_link" />
    <child link="wheel_2_link" />
    <axis xyz="0 0 1" />
  </joint>
  <link name="wheel_1_link">
    <inertial>
      <origin xyz="1.25478e-05 5.22294e-06 -0.000275017" rpy="3.14159 0 -3.14159" />
      <mass value="6.06820810020002" />
      <inertia ixx="0.0154034651258547" ixy="2.22604258305557E-06" ixz="5.22035462470836E-09" iyy="0.0154080256614685" iyz="-5.28562094376065E-09" izz="0.0297083471319844" />
    </inertial>
    <visual>
      <origin xyz="0 0 0" rpy="3.14159 0 -3.14159" />
      <geometry>
        <mesh filename="$(arg model_mesh_dir)/wheel_1_link.STL" />
      </geometry>
      <material name="">
        <color rgba="0.752941176470588 0.752941176470588 0.752941176470588 1" />
      </material>
    </visual>
    <collision name="wheel_1_collision_link">
      <origin xyz="0 0 0" rpy="3.14159 0 -3.14159" />
      <geometry>
        <mesh filename="$(arg model_mesh_dir)/wheel_1_collision_link.STL" />
      </geometry>
    </collision>
  </link>
  <joint name="wheel_1_joint" type="continuous">
    <origin xyz="-0.150688 0.087 0.072" rpy="-1.5708 0 -2.0944" />
    <parent link="base_link" />
    <child link="wheel_1_link" />
    <axis xyz="0 0 1" />
  </joint>
  <link name="wheel_0_link">
    <inertial>
      <origin xyz="1.25475e-05 5.22292e-06 -0.000275017" rpy="3.14159 0 3.14159" />
      <mass value="6.06820808425982" />
      <inertia ixx="0.0154034651445229" ixy="2.2260100097167E-06" ixz="5.20622353127761E-09" iyy="0.0154080256540422" iyz="-5.28522507555031E-09" izz="0.0297083471441777" />
    </inertial>
    <visual>
      <origin xyz="0 0 0" rpy="3.14159 0 3.14159" />
      <geometry>
        <mesh filename="$(arg model_mesh_dir)/wheel_0_link.STL" />
      </geometry>
      <material name="">
        <color rgba="0.752941176470588 0.752941176470588 0.752941176470588 1" />
      </material>
    </visual>
    <collision name="wheel_0_collision_link">
      <origin xyz="0 0 0" rpy="3.14159 0 3.14159" />
      <geometry>
        <mesh filename="$(arg model_mesh_dir)/wheel_0_collision_link.STL" />
      </geometry>
    </collision>
  </link>
  <joint name="wheel_0_joint" type="continuous">
    <origin xyz="0.150688 0.087 0.072" rpy="-1.5708 0 2.0944" />
    <parent link="base_link" />
    <child link="wheel_0_link" />
    <axis xyz="0 0 1" />
  </joint>
</robot>