<robot xmlns:xacro="http://www.ros.org/wiki/xacro" name="stretch">
  <link name="base_footprint">
    </link>
  <link name="base_link">
    <inertial>
      <origin xyz="0.000438847979969877 -0.00177714773743115 0.096468369649182" rpy="0 0 0" />
      <mass value="18.9261042191254" />
      <inertia ixx="0.21499266597667" ixy="0.000833860434673384" ixz="-0.000588719185658632" iyy="0.223010418927279" iyz="-0.00155067412786978" izz="0.327845794874634" />
    </inertial>
    <visual>
      <origin xyz="0 0 0" rpy="0 0 0" />
      <geometry>
        <mesh filename="$(arg model_mesh_dir)/base_link.obj" />
      </geometry>
      <material name="">
        <color rgba="0.752941176470588 0.752941176470588 0.752941176470588 1" />
      </material>
    </visual>
      <collision name="base_collision_link">
      <origin xyz="0 0 0" rpy="0 0 0" />
      <geometry>
        <mesh filename="$(arg model_mesh_dir)/base_collision_link.obj" />
      </geometry>
    </collision>
</link>
  <joint name="base_ref" type="fixed">
    <origin xyz="0 0 0.028" rpy="0 0 0" />
    <parent link="base_footprint" />
    <child link="base_link" />
    <axis xyz="0 0 0" />
  </joint>
  <link name="line_sensor_5_link">
    <inertial>
      <origin xyz="0.00114502070313138 0.0119761602719027 0.000126774756058469" rpy="0 0 0" />
      <mass value="0.00213836003346436" />
      <inertia ixx="2.88698160050487E-07" ixy="-7.07831726662329E-09" ixz="5.64135957062393E-10" iyy="6.64615782289848E-08" iyz="2.73972720709968E-10" izz="2.34959277592962E-07" />
    </inertial>
  </link>
  <joint name="line_sensor_5_joint" type="fixed">
    <origin xyz="0.0613832 0.178319 0.0527014" rpy="1.5708 0.453786 1.0472" />
    <parent link="base_link" />
    <child link="line_sensor_5_link" />
    <axis xyz="0 0 0" />
  </joint>
  <link name="line_sensor_5_optical_link">
    </link>
  <joint name="line_sensor_5_optical_joint" type="fixed">
    <origin xyz="0.00286 0 0" rpy="-1.5708 0 -1.5708" />
    <parent link="line_sensor_5_link" />
    <child link="line_sensor_5_optical_link" />
    <axis xyz="0 0 0" />
  </joint>
  <link name="line_sensor_4_link">
    <inertial>
      <origin xyz="0.00114502070313141 0.0119761602719027 0.000126774756058476" rpy="0 0 0" />
      <mass value="0.00213836003346436" />
      <inertia ixx="2.88698160050488E-07" ixy="-7.07831726662323E-09" ixz="5.64135957060038E-10" iyy="6.6461578228985E-08" iyz="2.73972720708377E-10" izz="2.34959277592962E-07" />
    </inertial>
  </link>
  <joint name="line_sensor_4_joint" type="fixed">
    <origin xyz="-0.0613832 0.178319 0.0527014" rpy="1.5708 0.453786 2.0944" />
    <parent link="base_link" />
    <child link="line_sensor_4_link" />
    <axis xyz="0 0 0" />
  </joint>
  <link name="line_sensor_4_optical_link">
    </link>
  <joint name="line_sensor_4_optical_joint" type="fixed">
    <origin xyz="0.00286 0 0" rpy="-1.5708 0 -1.5708" />
    <parent link="line_sensor_4_link" />
    <child link="line_sensor_4_optical_link" />
    <axis xyz="0 0 0" />
  </joint>
  <link name="line_sensor_3_link">
    <inertial>
      <origin xyz="0.00114502070313155 0.0119761602719025 0.000126774756058573" rpy="0 0 0" />
      <mass value="0.00213836003346444" />
      <inertia ixx="2.88698160050477E-07" ixy="-7.07831726660265E-09" ixz="5.64135957061257E-10" iyy="6.64615782289998E-08" iyz="2.73972720709266E-10" izz="2.34959277592965E-07" />
    </inertial>
  </link>
  <joint name="line_sensor_3_joint" type="fixed">
    <origin xyz="-0.18512 -0.036 0.0527014" rpy="1.5708 0.453786 -3.14159" />
    <parent link="base_link" />
    <child link="line_sensor_3_link" />
    <axis xyz="0 0 0" />
  </joint>
  <link name="line_sensor_3_optical_link">
    </link>
  <joint name="line_sensor_3_optical_joint" type="fixed">
    <origin xyz="0.00286 0 0" rpy="-1.5708 0 -1.5708" />
    <parent link="line_sensor_3_link" />
    <child link="line_sensor_3_optical_link" />
    <axis xyz="0 0 0" />
  </joint>
  <link name="line_sensor_2_link">
    <inertial>
      <origin xyz="0.00114502070313149 0.0119761602719027 0.000126774756058545" rpy="0 0 0" />
      <mass value="0.00213836003346437" />
      <inertia ixx="2.88698160050489E-07" ixy="-7.07831726662341E-09" ixz="5.64135957062458E-10" iyy="6.64615782289852E-08" iyz="2.73972720710036E-10" izz="2.34959277592963E-07" />
    </inertial>
  </link>
  <joint name="line_sensor_2_joint" type="fixed">
    <origin xyz="-0.123737 -0.142319 0.0527014" rpy="1.5708 0.453786 -2.0944" />
    <parent link="base_link" />
    <child link="line_sensor_2_link" />
    <axis xyz="0 0 0" />
  </joint>
  <link name="line_sensor_2_optical_link">
    </link>
  <joint name="line_sensor_2_optical_joint" type="fixed">
    <origin xyz="0.00286 0 0" rpy="-1.5708 0 -1.5708" />
    <parent link="line_sensor_2_link" />
    <child link="line_sensor_2_optical_link" />
    <axis xyz="0 0 0" />
  </joint>
  <link name="line_sensor_1_link">
    <inertial>
      <origin xyz="0.00114502070313141 0.0119761602719026 0.000126774756058601" rpy="0 0 0" />
      <mass value="0.00213836003346436" />
      <inertia ixx="2.88698160050487E-07" ixy="-7.07831726662332E-09" ixz="5.6413595706002E-10" iyy="6.64615782289848E-08" iyz="2.73972720708439E-10" izz="2.34959277592961E-07" />
    </inertial>
  </link>
  <joint name="line_sensor_1_joint" type="fixed">
    <origin xyz="0.123737 -0.142319 0.0527014" rpy="1.5708 0.453786 -1.0472" />
    <parent link="base_link" />
    <child link="line_sensor_1_link" />
    <axis xyz="0 0 0" />
  </joint>
  <link name="line_sensor_1_optical_link">
    </link>
  <joint name="line_sensor_1_optical_joint" type="fixed">
    <origin xyz="0.00286 0 0" rpy="-1.5708 0 -1.5708" />
    <parent link="line_sensor_1_link" />
    <child link="line_sensor_1_optical_link" />
    <axis xyz="0 0 0" />
  </joint>
  <link name="line_sensor_0_link">
    <inertial>
      <origin xyz="0.00114502070313233 0.0119761602719029 0.000126774756058746" rpy="0 0 0" />
      <mass value="0.00213836003346444" />
      <inertia ixx="2.88698160050477E-07" ixy="-7.07831726660256E-09" ixz="5.6413595706126E-10" iyy="6.64615782290001E-08" iyz="2.73972720709193E-10" izz="2.34959277592965E-07" />
    </inertial>
  </link>
  <joint name="line_sensor_0_joint" type="fixed">
    <origin xyz="0.18512 -0.036 0.0527014" rpy="1.5708 0.453786 0" />
    <parent link="base_link" />
    <child link="line_sensor_0_link" />
    <axis xyz="0 0 0" />
  </joint>
  <link name="line_sensor_0_optical_link">
    </link>
  <joint name="line_sensor_0_optical_joint" type="fixed">
    <origin xyz="0.00286 0 0" rpy="-1.5708 0 -1.5708" />
    <parent link="line_sensor_0_link" />
    <child link="line_sensor_0_optical_link" />
    <axis xyz="0 0 0" />
  </joint>
  <link name="head_link">
    <inertial>
      <origin xyz="0.0514013580104842 0.0986460644909709 -0.0250866227521696" rpy="0 0 0" />
      <mass value="5.12944639372071" />
      <inertia ixx="0.0380731695781352" ixy="0.000202619198715346" ixz="0.000237956614656072" iyy="0.0304351984631137" iyz="5.6169841247061E-05" izz="0.0637978570860214" />
    </inertial>
    <visual>
      <origin xyz="0 0 0" rpy="0 0 0" />
      <geometry>
        <mesh filename="$(arg model_mesh_dir)/head_link.obj" />
      </geometry>
      <material name="">
        <color rgba="0.752941176470588 0.752941176470588 0.752941176470588 1" />
      </material>
    </visual>
      <collision name="head_collision_link">
      <origin xyz="0 0 0" rpy="0 0 0" />
      <geometry>
        <mesh filename="$(arg model_mesh_dir)/head_collision_link.obj" />
      </geometry>
    </collision>
</link>
  <joint name="head_joint" type="fixed">
    <origin xyz="-0.093 -0.098 1.559" rpy="0 0 0" />
    <parent link="base_link" />
    <child link="head_link" />
    <axis xyz="0 0 0" />
  </joint>
  <link name="lidar_right_link">
    <inertial>
      <origin xyz="-3.20916615947908E-07 0.000175557811368021 -0.0150548418051187" rpy="0 0 0" />
      <mass value="0.240802480448075" />
      <inertia ixx="9.8041898749052E-05" ixy="4.48636958766777E-09" ixz="-3.11098715595503E-10" iyy="9.67162435587801E-05" iyz="1.39381302162429E-06" izz="0.000105657113395344" />
    </inertial>
  </link>
  <joint name="lidar_right_joint" type="fixed">
    <origin xyz="0.131744 -0.0264137 -0.058328" rpy="-3.05466 0.7816 2.39203" />
    <parent link="head_link" />
    <child link="lidar_right_link" />
    <axis xyz="0 0 0" />
  </joint>
  <link name="lidar_left_link">
    <inertial>
      <origin xyz="-3.87815889180132E-07 0.000175565758143037 -0.0150548416196863" rpy="0 0 0" />
      <mass value="0.240802531963034" />
      <inertia ixx="9.80418920755826E-05" ixy="4.46941117355771E-09" ixz="-3.09741336789929E-10" iyy="9.67162544690224E-05" iyz="1.39381215337495E-06" izz="0.000105657115998718" />
    </inertial>
  </link>
  <joint name="lidar_left_joint" type="fixed">
    <origin xyz="0.131744 0.222414 -0.058328" rpy="-3.05466 -0.7816 0.749563" />
    <parent link="head_link" />
    <child link="lidar_left_link" />
    <axis xyz="0 0 0" />
  </joint>
  <link name="camera_right_link">
    <inertial>
      <origin xyz="0.00778828 -0.00203277 0" rpy="0 1.5708 0" />
      <mass value="0.00595703520376034" />
      <inertia ixx="2.89408475364948E-07" ixy="-1.90971790692802E-22" ixz="-1.7205356741103E-22" iyy="2.54439535060776E-07" iyz="-2.64830205174192E-08" izz="3.91108473125467E-07" />
    </inertial>
  </link>
  <joint name="camera_right_joint" type="fixed">
    <origin xyz="0.171841 0.023 -0.0157567" rpy="0 0.820305 0" />
    <parent link="head_link" />
    <child link="camera_right_link" />
    <axis xyz="0 0 0" />
  </joint>
  <link name="camera_right_optical_link">
    </link>
  <joint name="camera_right_optical_joint" type="fixed">
    <origin xyz="0.0212 0 0" rpy="1.5708 0 1.5708" />
    <parent link="camera_right_link" />
    <child link="camera_right_optical_link" />
    <axis xyz="0 0 0" />
  </joint>
  <link name="camera_left_link">
    <inertial>
      <origin xyz="0.00778828 -0.00203277 0" rpy="0 1.5708 0" />
      <mass value="0.00595703520376035" />
      <inertia ixx="2.89408475364948E-07" ixy="6.77523478313298E-22" ixz="2.77932685817817E-22" iyy="2.54439535060776E-07" iyz="-2.64830205174189E-08" izz="3.91108473125467E-07" />
    </inertial>
  </link>
  <joint name="camera_left_joint" type="fixed">
    <origin xyz="0.171841 0.173 -0.0157567" rpy="3.14159 0.820305 0" />
    <parent link="head_link" />
    <child link="camera_left_link" />
    <axis xyz="0 0 0" />
  </joint>
  <link name="camera_left_optical_link">
    </link>
  <joint name="camera_left_optical_joint" type="fixed">
    <origin xyz="0.0212 0 0" rpy="1.5708 0 1.5708" />
    <parent link="camera_left_link" />
    <child link="camera_left_optical_link" />
    <axis xyz="0 0 0" />
  </joint>
  <link name="camera_center_link">
    <inertial>
      <origin xyz="0.000929405 -0.00250168 0" rpy="0 1.5708 0" />
      <mass value="0.00266363902430246" />
      <inertia ixx="1.23503897332185E-07" ixy="1.13386744265892E-23" ixz="-2.64697796016969E-23" iyy="1.05396694902143E-07" iyz="-6.23002529451325E-09" izz="2.021440741744E-07" />
    </inertial>
  </link>
  <joint name="camera_center_joint" type="fixed">
    <origin xyz="0.177246 0.098 -0.0239069" rpy="-3.14159 0.610865 0" />
    <parent link="head_link" />
    <child link="camera_center_link" />
    <axis xyz="0 0 0" />
  </joint>
  <link name="camera_center_optical_link">
    </link>
  <joint name="camera_center_optical_joint" type="fixed">
    <origin xyz="0.0017 0 0" rpy="-1.5708 0 -1.5708" />
    <parent link="camera_center_link" />
    <child link="camera_center_optical_link" />
    <axis xyz="0 0 0" />
  </joint>
  <link name="mast_link">
    <inertial>
      <origin xyz="2.77555756156289E-17 -0.00165282700965368 0.815" rpy="0 0 0" />
      <mass value="10.8924861076487" />
      <inertia ixx="1.96276319417158" ixy="-4.7689696841649E-18" ixz="-1.24526930733894E-16" iyy="1.96594229514087" iyz="-1.74684759963468E-18" izz="0.00577661764276332" />
    </inertial>
    <visual>
      <origin xyz="0 0 0" rpy="0 0 0" />
      <geometry>
        <mesh filename="$(arg model_mesh_dir)/mast_link.STL" />
      </geometry>
      <material name="">
        <color rgba="0.752941176470588 0.752941176470588 0.752941176470588 1" />
      </material>
    </visual>
    <collision name="mast_collision_link">
      <origin xyz="0 0 0" rpy="0 0 0" />
      <geometry>
        <mesh filename="$(arg model_mesh_dir)/mast_collision_link.STL" />
      </geometry>
    </collision>
  </link>
  <joint name="mast_joint" type="fixed">
    <origin xyz="-0.093 -0.098 0.004" rpy="0 0 0" />
    <parent link="base_link" />
    <child link="mast_link" />
    <axis xyz="0 0 0" />
  </joint>
  <link name="lift_link">
    <inertial>
      <origin xyz="-0.0148722581318624 0.0596072894254191 0.00542773918494432" rpy="0 0 0" />
      <mass value="2.95349364666659" />
      <inertia ixx="0.0117399464230091" ixy="0.000875437380496019" ixz="0.000164784888522662" iyy="0.0102748963241433" iyz="-0.00101918054718661" izz="0.0139841484528854" />
    </inertial>
    <visual>
      <origin xyz="0 0 0" rpy="0 0 0" />
      <geometry>
        <mesh filename="$(arg model_mesh_dir)/lift_link.STL" />
      </geometry>
      <material name="">
        <color rgba="0.752941176470588 0.752941176470588 0.752941176470588 1" />
      </material>
    </visual>
    <collision name="lift_collision_link">
      <origin xyz="0 0 0" rpy="0 0 0" />
      <geometry>
        <mesh filename="$(arg model_mesh_dir)/lift_collision_link.STL" />
      </geometry>
    </collision>
  </link>
  <joint name="lift_joint" type="prismatic">
    <origin xyz="0 -0.0014 0.241" rpy="0 0 0" />
    <parent link="mast_link" />
    <child link="lift_link" />
    <axis xyz="0 0 1" />
    <limit lower="0" upper="1.2" effort="0" velocity="0" />
  </joint>
  <link name="arm_l4_link">
    <inertial>
      <origin xyz="0.0146277 -0.0397927 0.0182873" rpy="0 1.5708 0" />
      <mass value="2.95349364666659" />
      <inertia ixx="0.0139841484528854" ixy="0.00101918054718661" ixz="-0.000164784888522663" iyy="0.0102748963241433" iyz="0.000875437380496019" izz="0.0117399464230091" />
    </inertial>
    <visual>
      <origin xyz="0 0 0" rpy="0 1.5708 0" />
      <geometry>
        <mesh filename="$(arg model_mesh_dir)/arm_l4_link.STL" />
      </geometry>
      <material name="">
        <color rgba="0.752941176470588 0.752941176470588 0.752941176470588 1" />
      </material>
    </visual>
    <collision name="arm_l4_collision_link">
      <origin xyz="0 0 0" rpy="0 1.5708 0" />
      <geometry>
        <mesh filename="$(arg model_mesh_dir)/arm_l4_collision_link.STL" />
      </geometry>
    </collision>
  </link>
  <joint name="arm_l4_joint" type="fixed">
    <origin xyz="-0.0295 0.0994 -0.0128595" rpy="0 0 0" />
    <parent link="lift_link" />
    <child link="arm_l4_link" />
    <axis xyz="0 0 0" />
  </joint>
  <link name="arm_l3_link">
    <inertial>
      <origin xyz="0.125319 0 0.00214616" rpy="0 1.5708 0" />
      <mass value="0.211728696447344" />
      <inertia ixx="0.000759408092665036" ixy="1.36043398852015E-21" ixz="-1.46222263151623E-10" iyy="0.000730798627565317" iyz="1.73119674800423E-19" izz="0.000227675228746485" />
    </inertial>
    <visual>
      <origin xyz="0 0 0" rpy="0 1.5708 0" />
      <geometry>
        <mesh filename="$(arg model_mesh_dir)/arm_l3_link.STL" />
      </geometry>
      <material name="">
        <color rgba="0.752941176470588 0.752941176470588 0.752941176470588 1" />
      </material>
    </visual>
    <collision name="arm_l3_collision_link">
      <origin xyz="0 0 0" rpy="0 1.5708 0" />
      <geometry>
        <mesh filename="$(arg model_mesh_dir)/arm_l3_collision_link.STL" />
      </geometry>
    </collision>
  </link>
  <joint name="arm_l3_joint" type="prismatic">
    <origin xyz="0.0055 0 0" rpy="0 0 0" />
    <parent link="arm_l4_link" />
    <child link="arm_l3_link" />
    <axis xyz="1 0 0" />
    <limit lower="0" upper="0.13" effort="0" velocity="0" />
  </joint>
  <link name="arm_l2_link">
    <inertial>
      <origin xyz="0.126545 0 0.00212533" rpy="0 1.5708 0" />
      <mass value="0.197181391808907" />
      <inertia ixx="0.000701571828521803" ixy="1.70789035181299E-21" ixz="-1.56735722682992E-10" iyy="0.000676905139492615" iyz="1.0639178603614E-19" izz="0.000180704361161813" />
    </inertial>
    <visual>
      <origin xyz="0 0 0" rpy="0 1.5708 0" />
      <geometry>
        <mesh filename="$(arg model_mesh_dir)/arm_l2_link.STL" />
      </geometry>
      <material name="">
        <color rgba="0.752941176470588 0.752941176470588 0.752941176470588 1" />
      </material>
    </visual>
    <collision name="arm_l2_collision_link">
      <origin xyz="0 0 0" rpy="0 1.5708 0" />
      <geometry>
        <mesh filename="$(arg model_mesh_dir)/arm_l2_collision_link.STL" />
      </geometry>
    </collision>
  </link>
  <joint name="arm_l2_joint" type="prismatic">
    <origin xyz="0.0135 0 0" rpy="0 0 0" />
    <parent link="arm_l3_link" />
    <child link="arm_l2_link" />
    <axis xyz="1 0 0" />
    <limit lower="0" upper="0.13" effort="0" velocity="0" />
  </joint>
  <link name="arm_l1_link">
    <inertial>
      <origin xyz="0.127806 0 0.00210076" rpy="0 1.5708 0" />
      <mass value="0.182379618165529" />
      <inertia ixx="0.000644687237937216" ixy="1.17464040780326E-20" ixz="-1.68878152441466E-10" iyy="0.00062371110107317" iyz="2.14435350061523E-19" izz="0.000140464382352664" />
    </inertial>
    <visual>
      <origin xyz="0 0 0" rpy="0 1.5708 0" />
      <geometry>
        <mesh filename="$(arg model_mesh_dir)/arm_l1_link.STL" />
      </geometry>
      <material name="">
        <color rgba="0.752941176470588 0.752941176470588 0.752941176470588 1" />
      </material>
    </visual>
    <collision name="arm_l1_collision_link">
      <origin xyz="0 0 0" rpy="0 1.5708 0" />
      <geometry>
        <mesh filename="$(arg model_mesh_dir)/arm_l1_collision_link.STL" />
      </geometry>
    </collision>
  </link>
  <joint name="arm_l1_joint" type="prismatic">
    <origin xyz="0.0135 0 0" rpy="0 0 0" />
    <parent link="arm_l2_link" />
    <child link="arm_l1_link" />
    <axis xyz="1 0 0" />
    <limit lower="0" upper="0.13" effort="0" velocity="0" />
  </joint>
  <link name="arm_l0_link">
    <inertial>
      <origin xyz="0.105 0 0.00206007" rpy="0 1.5708 0" />
      <mass value="0.131482025176648" />
      <inertia ixx="0.000527876279377435" ixy="1.07501867241791E-20" ixz="5.34785620504719E-20" iyy="0.00051464101554282" iyz="1.66616699804972E-19" izz="7.61244098718923E-05" />
    </inertial>
    <visual>
      <origin xyz="0 0 0" rpy="0 1.5708 0" />
      <geometry>
        <mesh filename="$(arg model_mesh_dir)/arm_l0_link.STL" />
      </geometry>
      <material name="">
        <color rgba="0.752941176470588 0.752941176470588 0.752941176470588 1" />
      </material>
    </visual>
    <collision name="arm_l0_collision_link">
      <origin xyz="0 0 0" rpy="0 1.5708 0" />
      <geometry>
        <mesh filename="$(arg model_mesh_dir)/arm_l0_collision_link.STL" />
      </geometry>
    </collision>
  </link>
  <joint name="arm_l0_joint" type="prismatic">
    <origin xyz="0.01375 0 0" rpy="0 0 0" />
    <parent link="arm_l1_link" />
    <child link="arm_l0_link" />
    <axis xyz="1 0 0" />
    <limit lower="0" upper="0.13" effort="0" velocity="0" />
  </joint>
  <link name="wrist_link">
    <inertial>
      <origin xyz="-0.00943224 0 0.035067" rpy="3.14159 0 3.14159" />
      <mass value="0.228848612237181" />
      <inertia ixx="0.000122470482540944" ixy="1.07472717306581E-10" ixz="1.16790939209657E-05" iyy="0.0001715213303575" iyz="9.50304167762594E-11" izz="0.000141511317394913" />
    </inertial>
    <visual>
      <origin xyz="0 0 0" rpy="3.14159 0 3.14159" />
      <geometry>
        <mesh filename="$(arg model_mesh_dir)/wrist_link.STL" />
      </geometry>
      <material name="">
        <color rgba="0.501960784313725 0.501960784313725 0.501960784313725 1" />
      </material>
    </visual>
    <collision name="wrist_collision_link">
      <origin xyz="0 0 0" rpy="3.14159 0 3.14159" />
      <geometry>
        <mesh filename="$(arg model_mesh_dir)/wrist_collision_link.STL" />
      </geometry>
    </collision>
  </link>
  <joint name="wrist_joint" type="fixed">
    <origin xyz="0.24715 0 -0.03672" rpy="0 0 0" />
    <parent link="arm_l0_link" />
    <child link="wrist_link" />
    <axis xyz="0 0 0" />
  </joint>
  <link name="wrist_yaw_link">
    <inertial>
      <origin xyz="0 -0.00772612 -0.0363543" rpy="3.14159 0 3.14159" />
      <mass value="0.217322026723881" />
      <inertia ixx="0.000154147840230305" ixy="-7.53840930670252E-11" ixz="-2.58411913184479E-10" iyy="0.000122233038608625" iyz="1.61976028021007E-05" izz="0.000116712065914663" />
    </inertial>
    <visual>
      <origin xyz="0 0 0" rpy="3.14159 0 3.14159" />
      <geometry>
        <mesh filename="$(arg model_mesh_dir)/wrist_yaw_link.STL" />
      </geometry>
      <material name="">
        <color rgba="0.792156862745098 0.819607843137255 0.933333333333333 1" />
      </material>
    </visual>
    <collision name="wrist_yaw_collision_link">
      <origin xyz="0 0 0" rpy="3.14159 0 3.14159" />
      <geometry>
        <mesh filename="$(arg model_mesh_dir)/wrist_yaw_collision_link.STL" />
      </geometry>
    </collision>
  </link>
  <joint name="wrist_yaw_joint" type="revolute">
    <origin xyz="0 0 0" rpy="0 0 0" />
    <parent link="wrist_link" />
    <child link="wrist_yaw_link" />
    <axis xyz="0 0 1" />
    <limit lower="-1.135" upper="4.276" effort="0" velocity="0" />
  </joint>
  <link name="wrist_pitch_link">
    <inertial>
      <origin xyz="0.00772612 -0.0363543 0" rpy="1.5708 -1.5708 0" />
      <mass value="0.217322026723367" />
      <inertia ixx="0.000154147840215896" ixy="-7.5383617586512E-11" ixz="-2.58413186795489E-10" iyy="0.000122233038608041" iyz="1.61976028014723E-05" izz="0.0001167120659007" />
    </inertial>
    <visual>
      <origin xyz="0 0 0" rpy="1.5708 -1.5708 0" />
      <geometry>
        <mesh filename="$(arg model_mesh_dir)/wrist_pitch_link.STL" />
      </geometry>
      <material name="">
        <color rgba="0.792156862745098 0.819607843137255 0.933333333333333 1" />
      </material>
    </visual>
    <collision name="wrist_pitch_collision_link">
      <origin xyz="0 0 0" rpy="1.5708 -1.5708 0" />
      <geometry>
        <mesh filename="$(arg model_mesh_dir)/wrist_pitch_collision_link.STL" />
      </geometry>
    </collision>
  </link>
  <joint name="wrist_pitch_joint" type="revolute">
    <origin xyz="0 -0.04222 -0.0452" rpy="0 0 0" />
    <parent link="wrist_yaw_link" />
    <child link="wrist_pitch_link" />
    <axis xyz="0 1 0" />
    <limit lower="-4.276" upper="1.135" effort="0" velocity="0" />
  </joint>
  <link name="wrist_roll_link">
    <inertial>
      <origin xyz="0.0125796 0.0013906 0.0122312" rpy="1.5708 0 1.5708" />
      <mass value="0.0875518779599177" />
      <inertia ixx="5.3109684066939E-05" ixy="2.53579489922103E-10" ixz="1.09648627070864E-11" iyy="2.50172844184434E-05" iyz="3.93918627087477E-06" izz="7.36573009473638E-05" />
    </inertial>
    <visual>
      <origin xyz="0 0 0" rpy="1.5708 0 1.5708" />
      <geometry>
        <mesh filename="$(arg model_mesh_dir)/wrist_roll_link.STL" />
      </geometry>
      <material name="">
        <color rgba="0.752941176470588 0.752941176470588 0.752941176470588 1" />
      </material>
    </visual>
    <collision name="wrist_roll_collision_link">
      <origin xyz="0 0 0" rpy="1.5708 0 1.5708" />
      <geometry>
        <mesh filename="$(arg model_mesh_dir)/wrist_roll_collision_link.STL" />
      </geometry>
    </collision>
  </link>
  <joint name="wrist_roll_joint" type="revolute">
    <origin xyz="0.04222 -0.0452 0" rpy="0 0 0" />
    <parent link="wrist_pitch_link" />
    <child link="wrist_roll_link" />
    <axis xyz="1 0 0" />
    <limit lower="-1.135" upper="4.276" effort="0" velocity="0" />
  </joint>
  <link name="gripper_camera_link">
    <inertial>
      <origin xyz="0 0.0120203 -0.00250349" rpy="0 0 -1.5708" />
      <mass value="0.0447759731526001" />
      <inertia ixx="1.60232107304684E-05" ixy="-8.65767518586304E-22" ixz="2.63946367478605E-08" iyy="6.92267971098109E-06" iyz="-6.09577361235966E-22" izz="1.36247235159961E-05" />
    </inertial>
    <visual>
      <origin xyz="0 0 0" rpy="0 0 -1.5708" />
      <geometry>
        <mesh filename="$(arg model_mesh_dir)/gripper_camera_link.STL" />
      </geometry>
      <material name="">
        <color rgba="0.792156862745098 0.819607843137255 0.933333333333333 1" />
      </material>
    </visual>
    <collision name="gripper_camera_collision_link">
      <origin xyz="0 0 0" rpy="0 0 -1.5708" />
      <geometry>
        <mesh filename="$(arg model_mesh_dir)/gripper_camera_collision_link.STL" />
      </geometry>
    </collision>
  </link>
  <joint name="gripper_camera_joint" type="fixed">
    <origin xyz="0.0192 0 0.057" rpy="-3.14159 0 -1.5708" />
    <parent link="wrist_roll_link" />
    <child link="gripper_camera_link" />
    <axis xyz="0 0 0" />
  </joint>
  <link name="gripper_stereo_camera_color_optical_frame">
    <visual>
      <origin xyz="0 0 0" rpy="0 0 1.5708" />
      <geometry>
        <box size="0.001 0.001 0.001" /></geometry>
      <material name="">
        <color rgba="0.792156862745098 0.819607843137255 0.933333333333333 1" />
      </material>
    </visual>
    </link>
  <joint name="gripper_stereo_camera_color_optical_joint" type="fixed">
    <origin xyz="0 0 0" rpy="3.14159 0 0" />
    <parent link="gripper_camera_link" />
    <child link="gripper_stereo_camera_color_optical_frame" />
    <axis xyz="0 0 0" />
  </joint>
  <link name="gripper_right_camera_color_optical_frame">
    <visual>
      <origin xyz="0 0 0" rpy="0 0 1.5708" />
      <geometry>
        <box size="0.001 0.001 0.001" /></geometry>
      <material name="">
        <color rgba="0.792156862745098 0.819607843137255 0.933333333333333 1" />
      </material>
    </visual>
    </link>
  <joint name="gripper_right_camera_color_optical_joint" type="fixed">
    <origin xyz="0.01 0 0" rpy="3.14159 0 0" />
    <parent link="gripper_camera_link" />
    <child link="gripper_right_camera_color_optical_frame" />
    <axis xyz="0 0 0" />
  </joint>
  <link name="gripper_left_camera_color_optical_frame">
    <visual>
      <origin xyz="0 0 0" rpy="0 0 1.5708" />
      <geometry>
        <box size="0.001 0.001 0.001" /></geometry>
      <material name="">
        <color rgba="0.792156862745098 0.819607843137255 0.933333333333333 1" />
      </material>
    </visual>
    </link>
  <joint name="gripper_left_camera_color_optical_joint" type="fixed">
    <origin xyz="-0.01 0 0" rpy="3.14159 0 0" />
    <parent link="gripper_camera_link" />
    <child link="gripper_left_camera_color_optical_frame" />
    <axis xyz="0 0 0" />
  </joint>
  <link name="tool_attachment_site_link">
    <inertial>
      <origin xyz="-0.00602038 0.0013906 0.0122312" rpy="-3.14159 -1.5708 0" />
      <mass value="0.0875518779599177" />
      <inertia ixx="2.50172844184434E-05" ixy="-2.53579489915028E-10" ixz="3.93918627087478E-06" iyy="5.3109684066939E-05" iyz="-1.09648626723268E-11" izz="7.36573009473638E-05" />
    </inertial>
    <visual>
      <origin xyz="0 0 0" rpy="-3.14159 -1.5708 0" />
      <geometry>
        <mesh filename="$(arg model_mesh_dir)/tool_attachment_site_link.STL" />
      </geometry>
      <material name="">
        <color rgba="0.752941176470588 0.752941176470588 0.752941176470588 1" />
      </material>
    </visual>
    <collision name="tool_attachment_site_collision_link">
      <origin xyz="0 0 0" rpy="-3.14159 -1.5708 0" />
      <geometry>
        <mesh filename="$(arg model_mesh_dir)/tool_attachment_site_collision_link.STL" />
      </geometry>
    </collision>
  </link>
  <joint name="tool_attachment_site_joint" type="fixed">
    <origin xyz="0.0186 0 0" rpy="0 0 0" />
    <parent link="wrist_roll_link" />
    <child link="tool_attachment_site_link" />
    <axis xyz="0 0 0" />
  </joint>
  <link name="wrist_aruco_link">
    <inertial>
      <origin xyz="8.97014e-06 2.99076e-06 0.000263517" rpy="3.14159 0 3.14159" />
      <mass value="0.000520487721584508" />
      <inertia ixx="3.834908442783E-08" ixy="-1.2363034580464E-14" ixz="1.34704395412487E-12" iyy="3.83685013633507E-08" iyz="-4.49121495198322E-13" izz="7.66888919510146E-08" />
    </inertial>
    <visual>
      <origin xyz="0 0 0" rpy="3.14159 0 3.14159" />
      <geometry>
        <mesh filename="$(arg model_mesh_dir)/wrist_aruco_link.STL" />
      </geometry>
      <material name="">
        <color rgba="1 1 1 1" />
      </material>
    </visual>
    <collision name="wrist_aruco_collision_link">
      <origin xyz="0 0 0" rpy="3.14159 0 3.14159" />
      <geometry>
        <mesh filename="$(arg model_mesh_dir)/wrist_aruco_collision_link.STL" />
      </geometry>
    </collision>
  </link>
  <joint name="wrist_aruco_joint" type="fixed">
    <origin xyz="-0.00867 0 0.0680605" rpy="3.14159 0 3.14159" />
    <parent link="wrist_link" />
    <child link="wrist_aruco_link" />
    <axis xyz="0 0 0" />
  </joint>
  <link name="wrist_reflector_link">
    <inertial>
      <origin xyz="-0.00377532 0 -0.00351761" rpy="3.14159 0 3.14159" />
      <mass value="0.00171618092746856" />
      <inertia ixx="1.51127728759546E-07" ixy="1.29437516224772E-17" ixz="-1.24862425165547E-09" iyy="1.64146246077095E-08" iyz="-2.00458433241248E-17" izz="1.47242352409892E-07" />
    </inertial>
    <visual>
      <origin xyz="0 0 0" rpy="3.14159 0 3.14159" />
      <geometry>
        <mesh filename="$(arg model_mesh_dir)/wrist_reflector_link.STL" />
      </geometry>
      <material name="">
        <color rgba="1 1 1 1" />
      </material>
    </visual>
    <collision name="wrist_reflector_collision_link">
      <origin xyz="0 0 0" rpy="3.14159 0 3.14159" />
      <geometry>
        <mesh filename="$(arg model_mesh_dir)/wrist_reflector_collision_link.STL" />
      </geometry>
    </collision>
  </link>
  <joint name="wrist_reflector_joint" type="fixed">
    <origin xyz="0.00665 0 0.0677605" rpy="3.14159 0 3.14159" />
    <parent link="wrist_link" />
    <child link="wrist_reflector_link" />
    <axis xyz="0 0 0" />
  </joint>
  <link name="wheel_2_link">
    <inertial>
      <origin xyz="1.25477e-05 5.22307e-06 -0.000275018" rpy="3.14159 0 3.14159" />
      <mass value="6.0682081887272" />
      <inertia ixx="0.0154034644119385" ixy="2.22604627484521E-06" ixz="5.21108774702266E-09" iyy="0.0154080256643557" iyz="-5.27262855356387E-09" izz="0.029708346400951" />
    </inertial>
    <visual>
      <origin xyz="0 0 0" rpy="3.14159 0 3.14159" />
      <geometry>
        <mesh filename="$(arg model_mesh_dir)/wheel_2_link.STL" />
      </geometry>
      <material name="">
        <color rgba="0.752941176470588 0.752941176470588 0.752941176470588 1" />
      </material>
    </visual>
    <collision name="wheel_2_collision_link">
      <origin xyz="0 0 0" rpy="3.14159 0 3.14159" />
      <geometry>
        <mesh filename="$(arg model_mesh_dir)/wheel_2_collision_link.STL" />
      </geometry>
    </collision>
  </link>
  <joint name="wheel_2_joint" type="continuous">
    <origin xyz="0 -0.174 0.072" rpy="-1.5708 0 0" />
    <parent link="base_link" />
    <child link="wheel_2_link" />
    <axis xyz="0 0 1" />
  </joint>
  <link name="wheel_1_link">
    <inertial>
      <origin xyz="1.25478e-05 5.22294e-06 -0.000275017" rpy="3.14159 0 3.14159" />
      <mass value="6.06820810020003" />
      <inertia ixx="0.0154034651258546" ixy="2.2260425830226E-06" ixz="5.22035462687677E-09" iyy="0.0154080256614686" iyz="-5.28562094398893E-09" izz="0.0297083471319844" />
    </inertial>
    <visual>
      <origin xyz="0 0 0" rpy="3.14159 0 3.14159" />
      <geometry>
        <mesh filename="$(arg model_mesh_dir)/wheel_1_link.STL" />
      </geometry>
      <material name="">
        <color rgba="0.752941176470588 0.752941176470588 0.752941176470588 1" />
      </material>
    </visual>
    <collision name="wheel_1_collision_link">
      <origin xyz="0 0 0" rpy="3.14159 0 3.14159" />
      <geometry>
        <mesh filename="$(arg model_mesh_dir)/wheel_1_collision_link.STL" />
      </geometry>
    </collision>
  </link>
  <joint name="wheel_1_joint" type="continuous">
    <origin xyz="-0.150688 0.087 0.072" rpy="-1.5708 0 -2.0944" />
    <parent link="base_link" />
    <child link="wheel_1_link" />
    <axis xyz="0 0 1" />
  </joint>
  <link name="wheel_0_link">
    <inertial>
      <origin xyz="1.25475e-05 5.22292e-06 -0.000275017" rpy="3.14159 0 3.14159" />
      <mass value="6.06820808425982" />
      <inertia ixx="0.0154034651445229" ixy="2.22601000971658E-06" ixz="5.20622353301233E-09" iyy="0.0154080256540422" iyz="-5.28522507546835E-09" izz="0.0297083471441777" />
    </inertial>
    <visual>
      <origin xyz="0 0 0" rpy="3.14159 0 3.14159" />
      <geometry>
        <mesh filename="$(arg model_mesh_dir)/wheel_0_link.STL" />
      </geometry>
      <material name="">
        <color rgba="0.752941176470588 0.752941176470588 0.752941176470588 1" />
      </material>
    </visual>
    <collision name="wheel_0_collision_link">
      <origin xyz="0 0 0" rpy="3.14159 0 3.14159" />
      <geometry>
        <mesh filename="$(arg model_mesh_dir)/wheel_0_collision_link.STL" />
      </geometry>
    </collision>
  </link>
  <joint name="wheel_0_joint" type="continuous">
    <origin xyz="0.150688 0.087 0.072" rpy="-1.5708 0 2.0944" />
    <parent link="base_link" />
    <child link="wheel_0_link" />
    <axis xyz="0 0 1" />
  </joint>
</robot>