<robot name="URDF_FRANCIS_ASSEM_Stretch_Gripper_V3">
  <link name="quick_connect_interface_link">
    <inertial>
      <origin xyz="0.0460466665213508 5.63314970979222E-06 -0.00837500592567954" rpy="0 0 0" />
      <mass value="0.268266992833353" />
      <inertia ixx="0.000142502024953855" ixy="2.76289213959696E-09" ixz="-2.23509988750753E-05" iyy="0.000269733509230681" iyz="-8.22584378581302E-09" izz="0.000235102926495123" />
    </inertial>
    <visual>
      <origin xyz="0 0 0" rpy="0 0 0" />
      <geometry>
        <mesh filename="$(arg tool_mesh_dir)/quick_connect_interface_link.STL" />
      </geometry>
      <material name="">
        <color rgba="0.752941176470588 0.752941176470588 0.752941176470588 1" />
      </material>
    </visual>
    <collision name="quick_connect_interface_collision_link">
      <origin xyz="0 0 0" rpy="0 0 0" />
      <geometry>
        <mesh filename="$(arg tool_mesh_dir)/quick_connect_interface_collision_link.STL" />
      </geometry>
    </collision>
  </link>
  <link name="gripper_finger_right_link">
    <inertial>
      <origin xyz="-0.0197363517714559 -3.17208639429321E-06 -0.102874799750023" rpy="0 0 0" />
      <mass value="0.0196451967584486" />
      <inertia ixx="5.78135538944762E-05" ixy="-4.000097909227E-09" ixz="-6.95117285138912E-06" iyy="6.49200844455989E-05" iyz="-7.1110705642277E-10" izz="7.66306924012398E-06" />
    </inertial>
    <visual>
      <origin xyz="0 0 0" rpy="0 0 0" />
      <geometry>
        <mesh filename="$(arg tool_mesh_dir)/gripper_finger_right_link.STL" />
      </geometry>
      <material name="">
        <color rgba="0.752941176470588 0.752941176470588 0.752941176470588 1" />
      </material>
    </visual>
    <collision name="gripper_finger_right_collision_link">
      <origin xyz="0 0 0" rpy="0 0 0" />
      <geometry>
        <mesh filename="$(arg tool_mesh_dir)/gripper_finger_right_collision_link.STL" />
      </geometry>
    </collision>
  </link>
  <joint name="gripper_finger_right_joint" type="revolute">
    <origin xyz="0.0377995041255281 -0.0221213818384166 0" rpy="1.5707963267949 0 -1.5707963267949" />
    <parent link="quick_connect_interface_link" />
    <child link="gripper_finger_right_link" />
    <axis xyz="0 -1 0" />
    <limit lower="0" upper="0.5" effort="0" velocity="0" />
  </joint>
  <link name="gripper_fingertip_right_link">
    <inertial>
      <origin xyz="0.000475558534248993 0.00831957442804077 -0.000277041398299914" rpy="0 0 0" />
      <mass value="0.0155505328279169" />
      <inertia ixx="2.74950777582773E-06" ixy="5.84692954757013E-08" ixz="5.92351921428352E-09" iyy="1.01134769547384E-06" iyz="7.19151436215247E-08" izz="2.1590127143644E-06" />
    </inertial>
    <visual>
      <origin xyz="0 0 0" rpy="0 0 0" />
      <geometry>
        <mesh filename="$(arg tool_mesh_dir)/gripper_fingertip_right_link.STL" />
      </geometry>
      <material name="">
        <color rgba="0.752941176470588 0.752941176470588 0 1" />
      </material>
    </visual>
    <collision name="gripper_fingertip_right_collision_link">
      <origin xyz="0 0 0" rpy="0 0 0" />
      <geometry>
        <mesh filename="$(arg tool_mesh_dir)/gripper_fingertip_right_collision_link.STL" />
      </geometry>
    </collision>
  </link>
  <joint name="gripper_fingertip_right_joint" type="fixed">
    <origin xyz="-0.0221679999883885 0 -0.191008332164326" rpy="1.5707963267949 0.279252680319109 -3.14159265358979" />
    <parent link="gripper_finger_right_link" />
    <child link="gripper_fingertip_right_link" />
    <axis xyz="0 0 0" />
  </joint>
  <link name="aruco_fingertip_right_link">
    <inertial>
      <origin xyz="-3.30439794460347E-06 -9.90743941896299E-06 -0.000211787813162015" rpy="0 0 0" />
      <mass value="0.000123521493853864" />
      <inertia ixx="3.33209068564967E-09" ixy="3.38901370000913E-15" ixz="7.62400928008393E-14" iyy="3.32883778612983E-09" iyz="2.28587510761889E-13" izz="6.65796010218536E-09" />
    </inertial>
    <visual>
      <origin xyz="0 0 0" rpy="0 0 0" />
      <geometry>
        <mesh filename="$(arg tool_mesh_dir)/aruco_fingertip_right_link.STL" />
      </geometry>
      <material name="">
        <color rgba="1 1 1 1" />
      </material>
    </visual>
    <collision name="aruco_fingertip_right_collision_link">
      <origin xyz="0 0 0" rpy="0 0 0" />
      <geometry>
        <mesh filename="$(arg tool_mesh_dir)/aruco_fingertip_right_collision_link.STL" />
      </geometry>
    </collision>
  </link>
  <joint name="aruco_fingertip_right_joint" type="fixed">
    <origin xyz="-0.00441710992520835 0.0320457043432331 0" rpy="1.37881010907552 0 2.44346095279206" />
    <parent link="gripper_fingertip_right_link" />
    <child link="aruco_fingertip_right_link" />
    <axis xyz="0 0 0" />
  </joint>
  <link name="gripper_finger_left_link">
    <inertial>
      <origin xyz="0.0197363612660075 3.17208444257828E-06 -0.102874202935414" rpy="0 0 0" />
      <mass value="0.0196452088457427" />
      <inertia ixx="5.78117539744567E-05" ixy="-4.00009729344883E-09" ixz="6.95129198318869E-06" iyy="6.49181938548344E-05" iyz="7.11145811406666E-10" izz="7.66297866728631E-06" />
    </inertial>
    <visual>
      <origin xyz="0 0 0" rpy="0 0 0" />
      <geometry>
        <mesh filename="$(arg tool_mesh_dir)/gripper_finger_left_link.STL" />
      </geometry>
      <material name="">
        <color rgba="0.752941176470588 0.752941176470588 0.752941176470588 1" />
      </material>
    </visual>
    <collision name="gripper_finger_left_collision_link">
      <origin xyz="0 0 0" rpy="0 0 0" />
      <geometry>
        <mesh filename="$(arg tool_mesh_dir)/gripper_finger_left_collision_link.STL" />
      </geometry>
    </collision>
  </link>
  <joint name="gripper_finger_left_joint" type="revolute">
    <origin xyz="0.0377995041255282 0.0221213818384166 0" rpy="1.5707963267949 0 -1.5707963267949" />
    <parent link="quick_connect_interface_link" />
    <child link="gripper_finger_left_link" />
    <axis xyz="0 -1 0" />
    <limit lower="-0.5" upper="0" effort="0" velocity="0" />
  </joint>
  <link name="gripper_fingertip_left_link">
    <inertial>
      <origin xyz="0.00047557820491366 -0.00831953155927476 -0.000277172441870529" rpy="0 0 0" />
      <mass value="0.0155504911063414" />
      <inertia ixx="2.74950563756043E-06" ixy="-5.84687401960287E-08" ixz="5.90317654774138E-09" iyy="1.01134446589953E-06" iyz="-7.19175556308359E-08" izz="2.15901353046032E-06" />
    </inertial>
    <visual>
      <origin xyz="0 0 0" rpy="0 0 0" />
      <geometry>
        <mesh filename="$(arg tool_mesh_dir)/gripper_fingertip_left_link.STL" />
      </geometry>
      <material name="">
        <color rgba="0.752941176470588 0.752941176470588 0 1" />
      </material>
    </visual>
    <collision name="gripper_fingertip_left_collision_link">
      <origin xyz="0 0 0" rpy="0 0 0" />
      <geometry>
        <mesh filename="$(arg tool_mesh_dir)/gripper_fingertip_left_collision_link.STL" />
      </geometry>
    </collision>
  </link>
  <joint name="gripper_fingertip_left_joint" type="fixed">
    <origin xyz="0.0221679999883927 0 -0.191008332164325" rpy="-1.5707963267949 0.279252680319088 0" />
    <parent link="gripper_finger_left_link" />
    <child link="gripper_fingertip_left_link" />
    <axis xyz="0 0 0" />
  </joint>
  <link name="aruco_fingertip_left_link">
    <inertial>
      <origin xyz="-3.30439794460347E-06 -9.90743941898381E-06 -0.000211787813162015" rpy="0 0 0" />
      <mass value="0.000123521493853863" />
      <inertia ixx="3.33209068564965E-09" ixy="3.38901368046699E-15" ixz="7.6240092801563E-14" iyy="3.32883778612979E-09" iyz="2.28587510763052E-13" izz="6.6579601021853E-09" />
    </inertial>
    <visual>
      <origin xyz="0 0 0" rpy="0 0 0" />
      <geometry>
        <mesh filename="$(arg tool_mesh_dir)/aruco_fingertip_left_link.STL" />
      </geometry>
      <material name="">
        <color rgba="1 1 1 1" />
      </material>
    </visual>
    <collision name="aruco_fingertip_left_collision_link">
      <origin xyz="0 0 0" rpy="0 0 0" />
      <geometry>
        <mesh filename="$(arg tool_mesh_dir)/aruco_fingertip_left_collision_link.STL" />
      </geometry>
    </collision>
  </link>
  <joint name="aruco_fingertip_left_joint" type="fixed">
    <origin xyz="-0.00441710992520833 -0.0320457043432331 0" rpy="1.37881010907552 0 0.698131700797736" />
    <parent link="gripper_fingertip_left_link" />
    <child link="aruco_fingertip_left_link" />
    <axis xyz="0 0 0" />
  </joint>
  <link name="grasp_center_link">
    <inertial>
      <origin xyz="2.77555756156289E-17 0 5.74053187100322E-20" rpy="0 0 0" />
      <mass value="6.54498469497874E-05" />
      <inertia ixx="1.63624617374468E-10" ixy="0" ixz="0" iyy="1.63624617374468E-10" iyz="0" izz="1.63624617374468E-10" />
    </inertial>
    <visual>
      <origin xyz="0 0 0" rpy="0 0 0" />
      <geometry>
        <mesh filename="$(arg tool_mesh_dir)/grasp_center_link.STL" />
      </geometry>
      <material name="">
        <color rgba="0.792156862745098 0.819607843137255 0.933333333333333 1" />
      </material>
    </visual>
    <collision name="grasp_center_collision_link">
      <origin xyz="0 0 0" rpy="0 0 0" />
      <geometry>
        <mesh filename="$(arg tool_mesh_dir)/grasp_center_collision_link.STL" />
      </geometry>
    </collision>
  </link>
  <joint name="grasp_center_joint" type="fixed">
    <origin xyz="0.23496234568483 0 0" rpy="0 0 0" />
    <parent link="quick_connect_interface_link" />
    <child link="grasp_center_link" />
    <axis xyz="0 0 0" />
  </joint>
</robot>