<robot name="URDF_FRANCIS_ASSEM_Stretch_Gripper_V6">
  <link name="quick_connect_interface_link">
    <inertial>
      <origin xyz="0.0460466663166456 5.63314975289596E-06 -0.00837500587558776" rpy="0 0 0" />
      <mass value="0.268266990446664" />
      <inertia ixx="0.000142502024751523" ixy="2.76289217435463E-09" ixz="-2.2350999156347E-05" iyy="0.000269733508018117" iyz="-8.22584379236226E-09" izz="0.000235102925220868" />
    </inertial>
    <visual>
      <origin xyz="0 0 0" rpy="0 0 0" />
      <geometry>
        <mesh filename="$(arg tool_mesh_dir)/quick_connect_interface_link.STL" />
      </geometry>
      <material name="">
        <color rgba="0.752941176470588 0.752941176470588 0.752941176470588 1" />
      </material>
    </visual>
    <collision name="quick_connect_interface_collision_link">
      <origin xyz="0 0 0" rpy="0 0 0" />
      <geometry>
        <mesh filename="$(arg tool_mesh_dir)/quick_connect_interface_collision_link.STL" />
      </geometry>
    </collision>
  </link>
  <link name="gripper_finger_right_link">
    <inertial>
      <origin xyz="0.102874799750023 -0.019736351771456 3.17208639429561E-06" rpy="0 0 0" />
      <mass value="0.0196451967584486" />
      <inertia ixx="7.66306924012396E-06" ixy="6.95117285138912E-06" ixz="-7.11107056420588E-10" iyy="5.78135538944762E-05" iyz="4.00009790922848E-09" izz="6.4920084445599E-05" />
    </inertial>
    <visual>
      <origin xyz="0 0 0" rpy="0 0 0" />
      <geometry>
        <mesh filename="$(arg tool_mesh_dir)/gripper_finger_right_link.STL" />
      </geometry>
      <material name="">
        <color rgba="0.752941176470588 0.752941176470588 0.752941176470588 1" />
      </material>
    </visual>
    <collision name="gripper_finger_right_collision_link">
      <origin xyz="0 0 0" rpy="0 0 0" />
      <geometry>
        <mesh filename="$(arg tool_mesh_dir)/gripper_finger_right_collision_link.STL" />
      </geometry>
    </collision>
  </link>
  <joint name="gripper_finger_right_joint" type="revolute">
    <origin xyz="0.0377995041255281 -0.0221213818384166 0" rpy="3.14159265358979 0 0" />
    <parent link="quick_connect_interface_link" />
    <child link="gripper_finger_right_link" />
    <axis xyz="0 0 1" />
    <limit lower="0" upper="0.5" effort="0" velocity="0" />
  </joint>
  <link name="gripper_fingertip_right_link">
    <inertial>
      <origin xyz="0.000475558534248993 0.00831957442804077 -0.000277041398299914" rpy="0 0 0" />
      <mass value="0.0155505328279169" />
      <inertia ixx="2.74950777582773E-06" ixy="5.84692954757014E-08" ixz="5.92351921428346E-09" iyy="1.01134769547383E-06" iyz="7.19151436215247E-08" izz="2.1590127143644E-06" />
    </inertial>
    <visual>
      <origin xyz="0 0 0" rpy="0 0 0" />
      <geometry>
        <mesh filename="$(arg tool_mesh_dir)/gripper_fingertip_right_link.STL" />
      </geometry>
      <material name="">
        <color rgba="0.752941176470588 0.752941176470588 0 1" />
      </material>
    </visual>
    <collision name="gripper_fingertip_right_collision_link">
      <origin xyz="0 0 0" rpy="0 0 0" />
      <geometry>
        <mesh filename="$(arg tool_mesh_dir)/gripper_fingertip_right_collision_link.STL" />
      </geometry>
    </collision>
  </link>
  <joint name="gripper_fingertip_right_joint" type="fixed">
    <origin xyz="0.191008332164326 -0.0221679999883885 0" rpy="3.14159265358979 0 -1.29154364647579" />
    <parent link="gripper_finger_right_link" />
    <child link="gripper_fingertip_right_link" />
    <axis xyz="0 0 0" />
  </joint>
  <link name="aruco_fingertip_right_link">
    <inertial>
      <origin xyz="-3.30439794460347E-06 -9.90743941896299E-06 -0.000211787813162015" rpy="0 0 0" />
      <mass value="0.000123521493853864" />
      <inertia ixx="3.33209068564967E-09" ixy="3.38901370003498E-15" ixz="7.62400928010461E-14" iyy="3.32883778612983E-09" iyz="2.28587510762354E-13" izz="6.65796010218536E-09" />
    </inertial>
    <visual>
      <origin xyz="0 0 0" rpy="0 0 0" />
      <geometry>
        <mesh filename="$(arg tool_mesh_dir)/aruco_fingertip_right_link.STL" />
      </geometry>
      <material name="">
        <color rgba="1 1 1 1" />
      </material>
    </visual>
    <collision name="aruco_fingertip_right_collision_link">
      <origin xyz="0 0 0" rpy="0 0 0" />
      <geometry>
        <mesh filename="$(arg tool_mesh_dir)/aruco_fingertip_right_collision_link.STL" />
      </geometry>
    </collision>
  </link>
  <joint name="aruco_fingertip_right_joint" type="fixed">
    <origin xyz="-0.00441710992520835 0.0320457043432331 0" rpy="1.37881010907552 0 2.44346095279206" />
    <parent link="gripper_fingertip_right_link" />
    <child link="aruco_fingertip_right_link" />
    <axis xyz="0 0 0" />
  </joint>
  <link name="gripper_finger_left_link">
    <inertial>
      <origin xyz="0.102874202935414 -0.0197363612660075 3.17208444257557E-06" rpy="0 0 0" />
      <mass value="0.0196452088457426" />
      <inertia ixx="7.6629786672863E-06" ixy="6.95129198318871E-06" ixz="-7.11145811406909E-10" iyy="5.78117539744567E-05" iyz="4.0000972934487E-09" izz="6.49181938548344E-05" />
    </inertial>
    <visual>
      <origin xyz="0 0 0" rpy="0 0 0" />
      <geometry>
        <mesh filename="$(arg tool_mesh_dir)/gripper_finger_left_link.STL" />
      </geometry>
      <material name="">
        <color rgba="0.752941176470588 0.752941176470588 0.752941176470588 1" />
      </material>
    </visual>
    <collision name="gripper_finger_left_collision_link">
      <origin xyz="0 0 0" rpy="0 0 0" />
      <geometry>
        <mesh filename="$(arg tool_mesh_dir)/gripper_finger_left_collision_link.STL" />
      </geometry>
    </collision>
  </link>
  <joint name="gripper_finger_left_joint" type="revolute">
    <origin xyz="0.0378 0.022121 0" rpy="0 0 0" />
    <parent link="quick_connect_interface_link" />
    <child link="gripper_finger_left_link" />
    <axis xyz="0 0 1" />
    <limit lower="0" upper="0.5" effort="0" velocity="0" />
  </joint>
  <link name="gripper_fingertip_left_link">
    <inertial>
      <origin xyz="0.000475578204913674 -0.00831953155927476 -0.000277172441870529" rpy="0 0 0" />
      <mass value="0.0155504911063414" />
      <inertia ixx="2.74950563756043E-06" ixy="-5.84687401960287E-08" ixz="5.90317654774139E-09" iyy="1.01134446589953E-06" iyz="-7.19175556308356E-08" izz="2.15901353046032E-06" />
    </inertial>
    <visual>
      <origin xyz="0 0 0" rpy="0 0 0" />
      <geometry>
        <mesh filename="$(arg tool_mesh_dir)/gripper_fingertip_left_link.STL" />
      </geometry>
      <material name="">
        <color rgba="0.752941176470588 0.752941176470588 0 1" />
      </material>
    </visual>
    <collision name="gripper_fingertip_left_collision_link">
      <origin xyz="0 0 0" rpy="0 0 0" />
      <geometry>
        <mesh filename="$(arg tool_mesh_dir)/gripper_fingertip_left_collision_link.STL" />
      </geometry>
    </collision>
  </link>
  <joint name="gripper_fingertip_left_joint" type="fixed">
    <origin xyz="0.191008332164325 -0.0221679999883927 0" rpy="0 0 -1.29154364647581" />
    <parent link="gripper_finger_left_link" />
    <child link="gripper_fingertip_left_link" />
    <axis xyz="0 0 0" />
  </joint>
  <link name="aruco_fingertip_left_link">
    <inertial>
      <origin xyz="-3.30439794460347E-06 -9.90743941898381E-06 -0.000211787813162015" rpy="0 0 0" />
      <mass value="0.000123521493853863" />
      <inertia ixx="3.33209068564965E-09" ixy="3.3890136800534E-15" ixz="7.62400928023902E-14" iyy="3.32883778612979E-09" iyz="2.28587510762548E-13" izz="6.6579601021853E-09" />
    </inertial>
    <visual>
      <origin xyz="0 0 0" rpy="0 0 0" />
      <geometry>
        <mesh filename="$(arg tool_mesh_dir)/aruco_fingertip_left_link.STL" />
      </geometry>
      <material name="">
        <color rgba="1 1 1 1" />
      </material>
    </visual>
    <collision name="aruco_fingertip_left_collision_link">
      <origin xyz="0 0 0" rpy="0 0 0" />
      <geometry>
        <mesh filename="$(arg tool_mesh_dir)/aruco_fingertip_left_collision_link.STL" />
      </geometry>
    </collision>
  </link>
  <joint name="aruco_fingertip_left_joint" type="fixed">
    <origin xyz="-0.00441710992520833 -0.0320457043432331 0" rpy="1.37881010907552 0 0.698131700797736" />
    <parent link="gripper_fingertip_left_link" />
    <child link="aruco_fingertip_left_link" />
    <axis xyz="0 0 0" />
  </joint>
  <link name="grasp_center_link" />
  <joint name="grasp_center_joint" type="fixed">
    <origin xyz="0.23496234568483 0 0" rpy="0 0 0" />
    <parent link="quick_connect_interface_link" />
    <child link="grasp_center_link" />
    <axis xyz="0 0 0" />
  </joint>
</robot>